2024-10-17 14:01:23,350 ERROR Error: 404 Not Found: The requested URL was not found on the server. If you entered the URL manually please check your spelling and try again.
Traceback (most recent call last):
  File "/usr/local/lib/python3.9/site-packages/flask/app.py", line 880, in full_dispatch_request
    rv = self.dispatch_request()
  File "/usr/local/lib/python3.9/site-packages/flask/app.py", line 854, in dispatch_request
    self.raise_routing_exception(req)
  File "/usr/local/lib/python3.9/site-packages/flask/app.py", line 463, in raise_routing_exception
    raise request.routing_exception  # type: ignore[misc]
  File "/usr/local/lib/python3.9/site-packages/flask/ctx.py", line 362, in match_request
    result = self.url_adapter.match(return_rule=True)  # type: ignore
  File "/usr/local/lib/python3.9/site-packages/werkzeug/routing/map.py", line 629, in match
    raise NotFound() from None
werkzeug.exceptions.NotFound: 404 Not Found: The requested URL was not found on the server. If you entered the URL manually please check your spelling and try again.
2024-10-17 14:01:28,855 ERROR Error: 404 Not Found: The requested URL was not found on the server. If you entered the URL manually please check your spelling and try again.
Traceback (most recent call last):
  File "/usr/local/lib/python3.9/site-packages/flask/app.py", line 880, in full_dispatch_request
    rv = self.dispatch_request()
  File "/usr/local/lib/python3.9/site-packages/flask/app.py", line 854, in dispatch_request
    self.raise_routing_exception(req)
  File "/usr/local/lib/python3.9/site-packages/flask/app.py", line 463, in raise_routing_exception
    raise request.routing_exception  # type: ignore[misc]
  File "/usr/local/lib/python3.9/site-packages/flask/ctx.py", line 362, in match_request
    result = self.url_adapter.match(return_rule=True)  # type: ignore
  File "/usr/local/lib/python3.9/site-packages/werkzeug/routing/map.py", line 629, in match
    raise NotFound() from None
werkzeug.exceptions.NotFound: 404 Not Found: The requested URL was not found on the server. If you entered the URL manually please check your spelling and try again.
2024-10-17 14:01:35,407 ERROR Error: Test exception for error logging
Traceback (most recent call last):
  File "/usr/local/lib/python3.9/site-packages/flask/app.py", line 880, in full_dispatch_request
    rv = self.dispatch_request()
  File "/usr/local/lib/python3.9/site-packages/flask/app.py", line 865, in dispatch_request
    return self.ensure_sync(self.view_functions[rule.endpoint])(**view_args)  # type: ignore[no-any-return]
  File "/app/app.py", line 32, in trigger_error
    raise Exception("Test exception for error logging")
Exception: Test exception for error logging
2024-10-17 14:01:35,459 ERROR Error: 404 Not Found: The requested URL was not found on the server. If you entered the URL manually please check your spelling and try again.
Traceback (most recent call last):
  File "/usr/local/lib/python3.9/site-packages/flask/app.py", line 880, in full_dispatch_request
    rv = self.dispatch_request()
  File "/usr/local/lib/python3.9/site-packages/flask/app.py", line 854, in dispatch_request
    self.raise_routing_exception(req)
  File "/usr/local/lib/python3.9/site-packages/flask/app.py", line 463, in raise_routing_exception
    raise request.routing_exception  # type: ignore[misc]
  File "/usr/local/lib/python3.9/site-packages/flask/ctx.py", line 362, in match_request
    result = self.url_adapter.match(return_rule=True)  # type: ignore
  File "/usr/local/lib/python3.9/site-packages/werkzeug/routing/map.py", line 629, in match
    raise NotFound() from None
werkzeug.exceptions.NotFound: 404 Not Found: The requested URL was not found on the server. If you entered the URL manually please check your spelling and try again.
2024-10-17 14:01:54,553 ERROR Error: 404 Not Found: The requested URL was not found on the server. If you entered the URL manually please check your spelling and try again.
Traceback (most recent call last):
  File "/usr/local/lib/python3.9/site-packages/flask/app.py", line 880, in full_dispatch_request
    rv = self.dispatch_request()
  File "/usr/local/lib/python3.9/site-packages/flask/app.py", line 854, in dispatch_request
    self.raise_routing_exception(req)
  File "/usr/local/lib/python3.9/site-packages/flask/app.py", line 463, in raise_routing_exception
    raise request.routing_exception  # type: ignore[misc]
  File "/usr/local/lib/python3.9/site-packages/flask/ctx.py", line 362, in match_request
    result = self.url_adapter.match(return_rule=True)  # type: ignore
  File "/usr/local/lib/python3.9/site-packages/werkzeug/routing/map.py", line 629, in match
    raise NotFound() from None
werkzeug.exceptions.NotFound: 404 Not Found: The requested URL was not found on the server. If you entered the URL manually please check your spelling and try again.
2024-10-17 14:02:02,218 ERROR Error: Test exception for error logging
Traceback (most recent call last):
  File "/usr/local/lib/python3.9/site-packages/flask/app.py", line 880, in full_dispatch_request
    rv = self.dispatch_request()
  File "/usr/local/lib/python3.9/site-packages/flask/app.py", line 865, in dispatch_request
    return self.ensure_sync(self.view_functions[rule.endpoint])(**view_args)  # type: ignore[no-any-return]
  File "/app/app.py", line 32, in trigger_error
    raise Exception("Test exception for error logging")
Exception: Test exception for error logging
2024-10-17 14:02:02,269 ERROR Error: 404 Not Found: The requested URL was not found on the server. If you entered the URL manually please check your spelling and try again.
Traceback (most recent call last):
  File "/usr/local/lib/python3.9/site-packages/flask/app.py", line 880, in full_dispatch_request
    rv = self.dispatch_request()
  File "/usr/local/lib/python3.9/site-packages/flask/app.py", line 854, in dispatch_request
    self.raise_routing_exception(req)
  File "/usr/local/lib/python3.9/site-packages/flask/app.py", line 463, in raise_routing_exception
    raise request.routing_exception  # type: ignore[misc]
  File "/usr/local/lib/python3.9/site-packages/flask/ctx.py", line 362, in match_request
    result = self.url_adapter.match(return_rule=True)  # type: ignore
  File "/usr/local/lib/python3.9/site-packages/werkzeug/routing/map.py", line 629, in match
    raise NotFound() from None
werkzeug.exceptions.NotFound: 404 Not Found: The requested URL was not found on the server. If you entered the URL manually please check your spelling and try again.
2024-10-17 14:02:29,754 ERROR Error: Test exception for error logging
Traceback (most recent call last):
  File "/usr/local/lib/python3.9/site-packages/flask/app.py", line 880, in full_dispatch_request
    rv = self.dispatch_request()
  File "/usr/local/lib/python3.9/site-packages/flask/app.py", line 865, in dispatch_request
    return self.ensure_sync(self.view_functions[rule.endpoint])(**view_args)  # type: ignore[no-any-return]
  File "/app/app.py", line 32, in trigger_error
    raise Exception("Test exception for error logging")
Exception: Test exception for error logging
2024-10-17 14:02:29,803 ERROR Error: 404 Not Found: The requested URL was not found on the server. If you entered the URL manually please check your spelling and try again.
Traceback (most recent call last):
  File "/usr/local/lib/python3.9/site-packages/flask/app.py", line 880, in full_dispatch_request
    rv = self.dispatch_request()
  File "/usr/local/lib/python3.9/site-packages/flask/app.py", line 854, in dispatch_request
    self.raise_routing_exception(req)
  File "/usr/local/lib/python3.9/site-packages/flask/app.py", line 463, in raise_routing_exception
    raise request.routing_exception  # type: ignore[misc]
  File "/usr/local/lib/python3.9/site-packages/flask/ctx.py", line 362, in match_request
    result = self.url_adapter.match(return_rule=True)  # type: ignore
  File "/usr/local/lib/python3.9/site-packages/werkzeug/routing/map.py", line 629, in match
    raise NotFound() from None
werkzeug.exceptions.NotFound: 404 Not Found: The requested URL was not found on the server. If you entered the URL manually please check your spelling and try again.
2024-10-17 14:02:30,621 ERROR Error: Test exception for error logging
Traceback (most recent call last):
  File "/usr/local/lib/python3.9/site-packages/flask/app.py", line 880, in full_dispatch_request
    rv = self.dispatch_request()
  File "/usr/local/lib/python3.9/site-packages/flask/app.py", line 865, in dispatch_request
    return self.ensure_sync(self.view_functions[rule.endpoint])(**view_args)  # type: ignore[no-any-return]
  File "/app/app.py", line 32, in trigger_error
    raise Exception("Test exception for error logging")
Exception: Test exception for error logging
2024-10-17 14:02:30,666 ERROR Error: 404 Not Found: The requested URL was not found on the server. If you entered the URL manually please check your spelling and try again.
Traceback (most recent call last):
  File "/usr/local/lib/python3.9/site-packages/flask/app.py", line 880, in full_dispatch_request
    rv = self.dispatch_request()
  File "/usr/local/lib/python3.9/site-packages/flask/app.py", line 854, in dispatch_request
    self.raise_routing_exception(req)
  File "/usr/local/lib/python3.9/site-packages/flask/app.py", line 463, in raise_routing_exception
    raise request.routing_exception  # type: ignore[misc]
  File "/usr/local/lib/python3.9/site-packages/flask/ctx.py", line 362, in match_request
    result = self.url_adapter.match(return_rule=True)  # type: ignore
  File "/usr/local/lib/python3.9/site-packages/werkzeug/routing/map.py", line 629, in match
    raise NotFound() from None
werkzeug.exceptions.NotFound: 404 Not Found: The requested URL was not found on the server. If you entered the URL manually please check your spelling and try again.
2024-10-17 14:02:34,087 ERROR Error: Test exception for error logging
Traceback (most recent call last):
  File "/usr/local/lib/python3.9/site-packages/flask/app.py", line 880, in full_dispatch_request
    rv = self.dispatch_request()
  File "/usr/local/lib/python3.9/site-packages/flask/app.py", line 865, in dispatch_request
    return self.ensure_sync(self.view_functions[rule.endpoint])(**view_args)  # type: ignore[no-any-return]
  File "/app/app.py", line 32, in trigger_error
    raise Exception("Test exception for error logging")
Exception: Test exception for error logging
2024-10-17 14:02:34,139 ERROR Error: 404 Not Found: The requested URL was not found on the server. If you entered the URL manually please check your spelling and try again.
Traceback (most recent call last):
  File "/usr/local/lib/python3.9/site-packages/flask/app.py", line 880, in full_dispatch_request
    rv = self.dispatch_request()
  File "/usr/local/lib/python3.9/site-packages/flask/app.py", line 854, in dispatch_request
    self.raise_routing_exception(req)
  File "/usr/local/lib/python3.9/site-packages/flask/app.py", line 463, in raise_routing_exception
    raise request.routing_exception  # type: ignore[misc]
  File "/usr/local/lib/python3.9/site-packages/flask/ctx.py", line 362, in match_request
    result = self.url_adapter.match(return_rule=True)  # type: ignore
  File "/usr/local/lib/python3.9/site-packages/werkzeug/routing/map.py", line 629, in match
    raise NotFound() from None
werkzeug.exceptions.NotFound: 404 Not Found: The requested URL was not found on the server. If you entered the URL manually please check your spelling and try again.
2024-10-17 14:02:34,268 ERROR Error: Test exception for error logging
Traceback (most recent call last):
  File "/usr/local/lib/python3.9/site-packages/flask/app.py", line 880, in full_dispatch_request
    rv = self.dispatch_request()
  File "/usr/local/lib/python3.9/site-packages/flask/app.py", line 865, in dispatch_request
    return self.ensure_sync(self.view_functions[rule.endpoint])(**view_args)  # type: ignore[no-any-return]
  File "/app/app.py", line 32, in trigger_error
    raise Exception("Test exception for error logging")
Exception: Test exception for error logging
2024-10-17 14:02:34,307 ERROR Error: 404 Not Found: The requested URL was not found on the server. If you entered the URL manually please check your spelling and try again.
Traceback (most recent call last):
  File "/usr/local/lib/python3.9/site-packages/flask/app.py", line 880, in full_dispatch_request
    rv = self.dispatch_request()
  File "/usr/local/lib/python3.9/site-packages/flask/app.py", line 854, in dispatch_request
    self.raise_routing_exception(req)
  File "/usr/local/lib/python3.9/site-packages/flask/app.py", line 463, in raise_routing_exception
    raise request.routing_exception  # type: ignore[misc]
  File "/usr/local/lib/python3.9/site-packages/flask/ctx.py", line 362, in match_request
    result = self.url_adapter.match(return_rule=True)  # type: ignore
  File "/usr/local/lib/python3.9/site-packages/werkzeug/routing/map.py", line 629, in match
    raise NotFound() from None
werkzeug.exceptions.NotFound: 404 Not Found: The requested URL was not found on the server. If you entered the URL manually please check your spelling and try again.
2024-10-17 14:02:34,437 ERROR Error: Test exception for error logging
Traceback (most recent call last):
  File "/usr/local/lib/python3.9/site-packages/flask/app.py", line 880, in full_dispatch_request
    rv = self.dispatch_request()
  File "/usr/local/lib/python3.9/site-packages/flask/app.py", line 865, in dispatch_request
    return self.ensure_sync(self.view_functions[rule.endpoint])(**view_args)  # type: ignore[no-any-return]
  File "/app/app.py", line 32, in trigger_error
    raise Exception("Test exception for error logging")
Exception: Test exception for error logging
2024-10-17 14:02:34,477 ERROR Error: 404 Not Found: The requested URL was not found on the server. If you entered the URL manually please check your spelling and try again.
Traceback (most recent call last):
  File "/usr/local/lib/python3.9/site-packages/flask/app.py", line 880, in full_dispatch_request
    rv = self.dispatch_request()
  File "/usr/local/lib/python3.9/site-packages/flask/app.py", line 854, in dispatch_request
    self.raise_routing_exception(req)
  File "/usr/local/lib/python3.9/site-packages/flask/app.py", line 463, in raise_routing_exception
    raise request.routing_exception  # type: ignore[misc]
  File "/usr/local/lib/python3.9/site-packages/flask/ctx.py", line 362, in match_request
    result = self.url_adapter.match(return_rule=True)  # type: ignore
  File "/usr/local/lib/python3.9/site-packages/werkzeug/routing/map.py", line 629, in match
    raise NotFound() from None
werkzeug.exceptions.NotFound: 404 Not Found: The requested URL was not found on the server. If you entered the URL manually please check your spelling and try again.
2024-10-17 14:02:34,622 ERROR Error: Test exception for error logging
Traceback (most recent call last):
  File "/usr/local/lib/python3.9/site-packages/flask/app.py", line 880, in full_dispatch_request
    rv = self.dispatch_request()
  File "/usr/local/lib/python3.9/site-packages/flask/app.py", line 865, in dispatch_request
    return self.ensure_sync(self.view_functions[rule.endpoint])(**view_args)  # type: ignore[no-any-return]
  File "/app/app.py", line 32, in trigger_error
    raise Exception("Test exception for error logging")
Exception: Test exception for error logging
2024-10-17 14:02:34,658 ERROR Error: 404 Not Found: The requested URL was not found on the server. If you entered the URL manually please check your spelling and try again.
Traceback (most recent call last):
  File "/usr/local/lib/python3.9/site-packages/flask/app.py", line 880, in full_dispatch_request
    rv = self.dispatch_request()
  File "/usr/local/lib/python3.9/site-packages/flask/app.py", line 854, in dispatch_request
    self.raise_routing_exception(req)
  File "/usr/local/lib/python3.9/site-packages/flask/app.py", line 463, in raise_routing_exception
    raise request.routing_exception  # type: ignore[misc]
  File "/usr/local/lib/python3.9/site-packages/flask/ctx.py", line 362, in match_request
    result = self.url_adapter.match(return_rule=True)  # type: ignore
  File "/usr/local/lib/python3.9/site-packages/werkzeug/routing/map.py", line 629, in match
    raise NotFound() from None
werkzeug.exceptions.NotFound: 404 Not Found: The requested URL was not found on the server. If you entered the URL manually please check your spelling and try again.
2024-10-17 14:02:53,015 ERROR Error: Test exception for error logging
Traceback (most recent call last):
  File "/usr/local/lib/python3.9/site-packages/flask/app.py", line 880, in full_dispatch_request
    rv = self.dispatch_request()
  File "/usr/local/lib/python3.9/site-packages/flask/app.py", line 865, in dispatch_request
    return self.ensure_sync(self.view_functions[rule.endpoint])(**view_args)  # type: ignore[no-any-return]
  File "/app/app.py", line 32, in trigger_error
    raise Exception("Test exception for error logging")
Exception: Test exception for error logging
2024-10-17 14:02:53,065 ERROR Error: 404 Not Found: The requested URL was not found on the server. If you entered the URL manually please check your spelling and try again.
Traceback (most recent call last):
  File "/usr/local/lib/python3.9/site-packages/flask/app.py", line 880, in full_dispatch_request
    rv = self.dispatch_request()
  File "/usr/local/lib/python3.9/site-packages/flask/app.py", line 854, in dispatch_request
    self.raise_routing_exception(req)
  File "/usr/local/lib/python3.9/site-packages/flask/app.py", line 463, in raise_routing_exception
    raise request.routing_exception  # type: ignore[misc]
  File "/usr/local/lib/python3.9/site-packages/flask/ctx.py", line 362, in match_request
    result = self.url_adapter.match(return_rule=True)  # type: ignore
  File "/usr/local/lib/python3.9/site-packages/werkzeug/routing/map.py", line 629, in match
    raise NotFound() from None
werkzeug.exceptions.NotFound: 404 Not Found: The requested URL was not found on the server. If you entered the URL manually please check your spelling and try again.
2024-10-17 15:53:09,963 ERROR Error fetching data: 2003 (HY000): Can't connect to MySQL server on 'localhost:3306' (111)
Traceback (most recent call last):
  File "/usr/local/lib/python3.9/site-packages/mysql/connector/connection_cext.py", line 335, in _open_connection
    self._cmysql.connect(**cnx_kwargs)
_mysql_connector.MySQLInterfaceError: Can't connect to MySQL server on 'localhost:3306' (111)

The above exception was the direct cause of the following exception:

Traceback (most recent call last):
  File "/app/app.py", line 50, in get_data
    connection = mysql.connector.connect(**db_config)
  File "/usr/local/lib/python3.9/site-packages/mysql/connector/pooling.py", line 322, in connect
    return CMySQLConnection(*args, **kwargs)
  File "/usr/local/lib/python3.9/site-packages/mysql/connector/connection_cext.py", line 151, in __init__
    self.connect(**kwargs)
  File "/usr/local/lib/python3.9/site-packages/mysql/connector/abstracts.py", line 1426, in connect
    self._open_connection()
  File "/usr/local/lib/python3.9/site-packages/mysql/connector/connection_cext.py", line 340, in _open_connection
    raise get_mysql_exception(
mysql.connector.errors.DatabaseError: 2003 (HY000): Can't connect to MySQL server on 'localhost:3306' (111)
2024-10-17 15:55:19,292 ERROR Error fetching data: 2003 (HY000): Can't connect to MySQL server on 'localhost:3306' (111)
Traceback (most recent call last):
  File "/usr/local/lib/python3.9/site-packages/mysql/connector/connection_cext.py", line 335, in _open_connection
    self._cmysql.connect(**cnx_kwargs)
_mysql_connector.MySQLInterfaceError: Can't connect to MySQL server on 'localhost:3306' (111)

The above exception was the direct cause of the following exception:

Traceback (most recent call last):
  File "/app/app.py", line 50, in get_data
    connection = mysql.connector.connect(**db_config)
  File "/usr/local/lib/python3.9/site-packages/mysql/connector/pooling.py", line 322, in connect
    return CMySQLConnection(*args, **kwargs)
  File "/usr/local/lib/python3.9/site-packages/mysql/connector/connection_cext.py", line 151, in __init__
    self.connect(**kwargs)
  File "/usr/local/lib/python3.9/site-packages/mysql/connector/abstracts.py", line 1426, in connect
    self._open_connection()
  File "/usr/local/lib/python3.9/site-packages/mysql/connector/connection_cext.py", line 340, in _open_connection
    raise get_mysql_exception(
mysql.connector.errors.DatabaseError: 2003 (HY000): Can't connect to MySQL server on 'localhost:3306' (111)
2024-10-17 15:55:20,238 ERROR Error fetching data: 2003 (HY000): Can't connect to MySQL server on 'localhost:3306' (111)
Traceback (most recent call last):
  File "/usr/local/lib/python3.9/site-packages/mysql/connector/connection_cext.py", line 335, in _open_connection
    self._cmysql.connect(**cnx_kwargs)
_mysql_connector.MySQLInterfaceError: Can't connect to MySQL server on 'localhost:3306' (111)

The above exception was the direct cause of the following exception:

Traceback (most recent call last):
  File "/app/app.py", line 50, in get_data
    connection = mysql.connector.connect(**db_config)
  File "/usr/local/lib/python3.9/site-packages/mysql/connector/pooling.py", line 322, in connect
    return CMySQLConnection(*args, **kwargs)
  File "/usr/local/lib/python3.9/site-packages/mysql/connector/connection_cext.py", line 151, in __init__
    self.connect(**kwargs)
  File "/usr/local/lib/python3.9/site-packages/mysql/connector/abstracts.py", line 1426, in connect
    self._open_connection()
  File "/usr/local/lib/python3.9/site-packages/mysql/connector/connection_cext.py", line 340, in _open_connection
    raise get_mysql_exception(
mysql.connector.errors.DatabaseError: 2003 (HY000): Can't connect to MySQL server on 'localhost:3306' (111)
2024-10-17 15:55:20,954 ERROR Error fetching data: 2003 (HY000): Can't connect to MySQL server on 'localhost:3306' (111)
Traceback (most recent call last):
  File "/usr/local/lib/python3.9/site-packages/mysql/connector/connection_cext.py", line 335, in _open_connection
    self._cmysql.connect(**cnx_kwargs)
_mysql_connector.MySQLInterfaceError: Can't connect to MySQL server on 'localhost:3306' (111)

The above exception was the direct cause of the following exception:

Traceback (most recent call last):
  File "/app/app.py", line 50, in get_data
    connection = mysql.connector.connect(**db_config)
  File "/usr/local/lib/python3.9/site-packages/mysql/connector/pooling.py", line 322, in connect
    return CMySQLConnection(*args, **kwargs)
  File "/usr/local/lib/python3.9/site-packages/mysql/connector/connection_cext.py", line 151, in __init__
    self.connect(**kwargs)
  File "/usr/local/lib/python3.9/site-packages/mysql/connector/abstracts.py", line 1426, in connect
    self._open_connection()
  File "/usr/local/lib/python3.9/site-packages/mysql/connector/connection_cext.py", line 340, in _open_connection
    raise get_mysql_exception(
mysql.connector.errors.DatabaseError: 2003 (HY000): Can't connect to MySQL server on 'localhost:3306' (111)
2024-10-17 15:55:21,342 ERROR Error fetching data: 2003 (HY000): Can't connect to MySQL server on 'localhost:3306' (111)
Traceback (most recent call last):
  File "/usr/local/lib/python3.9/site-packages/mysql/connector/connection_cext.py", line 335, in _open_connection
    self._cmysql.connect(**cnx_kwargs)
_mysql_connector.MySQLInterfaceError: Can't connect to MySQL server on 'localhost:3306' (111)

The above exception was the direct cause of the following exception:

Traceback (most recent call last):
  File "/app/app.py", line 50, in get_data
    connection = mysql.connector.connect(**db_config)
  File "/usr/local/lib/python3.9/site-packages/mysql/connector/pooling.py", line 322, in connect
    return CMySQLConnection(*args, **kwargs)
  File "/usr/local/lib/python3.9/site-packages/mysql/connector/connection_cext.py", line 151, in __init__
    self.connect(**kwargs)
  File "/usr/local/lib/python3.9/site-packages/mysql/connector/abstracts.py", line 1426, in connect
    self._open_connection()
  File "/usr/local/lib/python3.9/site-packages/mysql/connector/connection_cext.py", line 340, in _open_connection
    raise get_mysql_exception(
mysql.connector.errors.DatabaseError: 2003 (HY000): Can't connect to MySQL server on 'localhost:3306' (111)
2024-10-17 15:55:21,514 ERROR Error fetching data: 2003 (HY000): Can't connect to MySQL server on 'localhost:3306' (111)
Traceback (most recent call last):
  File "/usr/local/lib/python3.9/site-packages/mysql/connector/connection_cext.py", line 335, in _open_connection
    self._cmysql.connect(**cnx_kwargs)
_mysql_connector.MySQLInterfaceError: Can't connect to MySQL server on 'localhost:3306' (111)

The above exception was the direct cause of the following exception:

Traceback (most recent call last):
  File "/app/app.py", line 50, in get_data
    connection = mysql.connector.connect(**db_config)
  File "/usr/local/lib/python3.9/site-packages/mysql/connector/pooling.py", line 322, in connect
    return CMySQLConnection(*args, **kwargs)
  File "/usr/local/lib/python3.9/site-packages/mysql/connector/connection_cext.py", line 151, in __init__
    self.connect(**kwargs)
  File "/usr/local/lib/python3.9/site-packages/mysql/connector/abstracts.py", line 1426, in connect
    self._open_connection()
  File "/usr/local/lib/python3.9/site-packages/mysql/connector/connection_cext.py", line 340, in _open_connection
    raise get_mysql_exception(
mysql.connector.errors.DatabaseError: 2003 (HY000): Can't connect to MySQL server on 'localhost:3306' (111)
2024-10-17 15:55:21,668 ERROR Error fetching data: 2003 (HY000): Can't connect to MySQL server on 'localhost:3306' (111)
Traceback (most recent call last):
  File "/usr/local/lib/python3.9/site-packages/mysql/connector/connection_cext.py", line 335, in _open_connection
    self._cmysql.connect(**cnx_kwargs)
_mysql_connector.MySQLInterfaceError: Can't connect to MySQL server on 'localhost:3306' (111)

The above exception was the direct cause of the following exception:

Traceback (most recent call last):
  File "/app/app.py", line 50, in get_data
    connection = mysql.connector.connect(**db_config)
  File "/usr/local/lib/python3.9/site-packages/mysql/connector/pooling.py", line 322, in connect
    return CMySQLConnection(*args, **kwargs)
  File "/usr/local/lib/python3.9/site-packages/mysql/connector/connection_cext.py", line 151, in __init__
    self.connect(**kwargs)
  File "/usr/local/lib/python3.9/site-packages/mysql/connector/abstracts.py", line 1426, in connect
    self._open_connection()
  File "/usr/local/lib/python3.9/site-packages/mysql/connector/connection_cext.py", line 340, in _open_connection
    raise get_mysql_exception(
mysql.connector.errors.DatabaseError: 2003 (HY000): Can't connect to MySQL server on 'localhost:3306' (111)
2024-10-17 15:55:21,883 ERROR Error fetching data: 2003 (HY000): Can't connect to MySQL server on 'localhost:3306' (111)
Traceback (most recent call last):
  File "/usr/local/lib/python3.9/site-packages/mysql/connector/connection_cext.py", line 335, in _open_connection
    self._cmysql.connect(**cnx_kwargs)
_mysql_connector.MySQLInterfaceError: Can't connect to MySQL server on 'localhost:3306' (111)

The above exception was the direct cause of the following exception:

Traceback (most recent call last):
  File "/app/app.py", line 50, in get_data
    connection = mysql.connector.connect(**db_config)
  File "/usr/local/lib/python3.9/site-packages/mysql/connector/pooling.py", line 322, in connect
    return CMySQLConnection(*args, **kwargs)
  File "/usr/local/lib/python3.9/site-packages/mysql/connector/connection_cext.py", line 151, in __init__
    self.connect(**kwargs)
  File "/usr/local/lib/python3.9/site-packages/mysql/connector/abstracts.py", line 1426, in connect
    self._open_connection()
  File "/usr/local/lib/python3.9/site-packages/mysql/connector/connection_cext.py", line 340, in _open_connection
    raise get_mysql_exception(
mysql.connector.errors.DatabaseError: 2003 (HY000): Can't connect to MySQL server on 'localhost:3306' (111)
2024-10-18 13:43:05,317 ERROR Error: 404 Not Found: The requested URL was not found on the server. If you entered the URL manually please check your spelling and try again.
Traceback (most recent call last):
  File "/usr/local/lib/python3.9/site-packages/flask/app.py", line 880, in full_dispatch_request
    rv = self.dispatch_request()
  File "/usr/local/lib/python3.9/site-packages/flask/app.py", line 854, in dispatch_request
    self.raise_routing_exception(req)
  File "/usr/local/lib/python3.9/site-packages/flask/app.py", line 463, in raise_routing_exception
    raise request.routing_exception  # type: ignore[misc]
  File "/usr/local/lib/python3.9/site-packages/flask/ctx.py", line 362, in match_request
    result = self.url_adapter.match(return_rule=True)  # type: ignore
  File "/usr/local/lib/python3.9/site-packages/werkzeug/routing/map.py", line 629, in match
    raise NotFound() from None
werkzeug.exceptions.NotFound: 404 Not Found: The requested URL was not found on the server. If you entered the URL manually please check your spelling and try again.
2024-10-18 13:43:12,401 ERROR Error: 405 Method Not Allowed: The method is not allowed for the requested URL.
Traceback (most recent call last):
  File "/usr/local/lib/python3.9/site-packages/flask/app.py", line 880, in full_dispatch_request
    rv = self.dispatch_request()
  File "/usr/local/lib/python3.9/site-packages/flask/app.py", line 854, in dispatch_request
    self.raise_routing_exception(req)
  File "/usr/local/lib/python3.9/site-packages/flask/app.py", line 463, in raise_routing_exception
    raise request.routing_exception  # type: ignore[misc]
  File "/usr/local/lib/python3.9/site-packages/flask/ctx.py", line 362, in match_request
    result = self.url_adapter.match(return_rule=True)  # type: ignore
  File "/usr/local/lib/python3.9/site-packages/werkzeug/routing/map.py", line 624, in match
    raise MethodNotAllowed(valid_methods=list(e.have_match_for)) from None
werkzeug.exceptions.MethodNotAllowed: 405 Method Not Allowed: The method is not allowed for the requested URL.
2024-10-18 13:43:12,485 ERROR Error: 404 Not Found: The requested URL was not found on the server. If you entered the URL manually please check your spelling and try again.
Traceback (most recent call last):
  File "/usr/local/lib/python3.9/site-packages/flask/app.py", line 880, in full_dispatch_request
    rv = self.dispatch_request()
  File "/usr/local/lib/python3.9/site-packages/flask/app.py", line 854, in dispatch_request
    self.raise_routing_exception(req)
  File "/usr/local/lib/python3.9/site-packages/flask/app.py", line 463, in raise_routing_exception
    raise request.routing_exception  # type: ignore[misc]
  File "/usr/local/lib/python3.9/site-packages/flask/ctx.py", line 362, in match_request
    result = self.url_adapter.match(return_rule=True)  # type: ignore
  File "/usr/local/lib/python3.9/site-packages/werkzeug/routing/map.py", line 629, in match
    raise NotFound() from None
werkzeug.exceptions.NotFound: 404 Not Found: The requested URL was not found on the server. If you entered the URL manually please check your spelling and try again.
2024-10-18 13:53:15,455 ERROR Error: 404 Not Found: The requested URL was not found on the server. If you entered the URL manually please check your spelling and try again.
Traceback (most recent call last):
  File "/usr/local/lib/python3.9/site-packages/flask/app.py", line 880, in full_dispatch_request
    rv = self.dispatch_request()
  File "/usr/local/lib/python3.9/site-packages/flask/app.py", line 854, in dispatch_request
    self.raise_routing_exception(req)
  File "/usr/local/lib/python3.9/site-packages/flask/app.py", line 463, in raise_routing_exception
    raise request.routing_exception  # type: ignore[misc]
  File "/usr/local/lib/python3.9/site-packages/flask/ctx.py", line 362, in match_request
    result = self.url_adapter.match(return_rule=True)  # type: ignore
  File "/usr/local/lib/python3.9/site-packages/werkzeug/routing/map.py", line 629, in match
    raise NotFound() from None
werkzeug.exceptions.NotFound: 404 Not Found: The requested URL was not found on the server. If you entered the URL manually please check your spelling and try again.
2024-10-18 14:25:59,595 ERROR Error: 404 Not Found: The requested URL was not found on the server. If you entered the URL manually please check your spelling and try again.
Traceback (most recent call last):
  File "/usr/local/lib/python3.9/site-packages/flask/app.py", line 880, in full_dispatch_request
    rv = self.dispatch_request()
  File "/usr/local/lib/python3.9/site-packages/flask/app.py", line 854, in dispatch_request
    self.raise_routing_exception(req)
  File "/usr/local/lib/python3.9/site-packages/flask/app.py", line 463, in raise_routing_exception
    raise request.routing_exception  # type: ignore[misc]
  File "/usr/local/lib/python3.9/site-packages/flask/ctx.py", line 362, in match_request
    result = self.url_adapter.match(return_rule=True)  # type: ignore
  File "/usr/local/lib/python3.9/site-packages/werkzeug/routing/map.py", line 629, in match
    raise NotFound() from None
werkzeug.exceptions.NotFound: 404 Not Found: The requested URL was not found on the server. If you entered the URL manually please check your spelling and try again.
2024-10-18 14:26:04,506 ERROR Error: 405 Method Not Allowed: The method is not allowed for the requested URL.
Traceback (most recent call last):
  File "/usr/local/lib/python3.9/site-packages/flask/app.py", line 880, in full_dispatch_request
    rv = self.dispatch_request()
  File "/usr/local/lib/python3.9/site-packages/flask/app.py", line 854, in dispatch_request
    self.raise_routing_exception(req)
  File "/usr/local/lib/python3.9/site-packages/flask/app.py", line 463, in raise_routing_exception
    raise request.routing_exception  # type: ignore[misc]
  File "/usr/local/lib/python3.9/site-packages/flask/ctx.py", line 362, in match_request
    result = self.url_adapter.match(return_rule=True)  # type: ignore
  File "/usr/local/lib/python3.9/site-packages/werkzeug/routing/map.py", line 624, in match
    raise MethodNotAllowed(valid_methods=list(e.have_match_for)) from None
werkzeug.exceptions.MethodNotAllowed: 405 Method Not Allowed: The method is not allowed for the requested URL.
2024-10-18 14:26:04,574 ERROR Error: 404 Not Found: The requested URL was not found on the server. If you entered the URL manually please check your spelling and try again.
Traceback (most recent call last):
  File "/usr/local/lib/python3.9/site-packages/flask/app.py", line 880, in full_dispatch_request
    rv = self.dispatch_request()
  File "/usr/local/lib/python3.9/site-packages/flask/app.py", line 854, in dispatch_request
    self.raise_routing_exception(req)
  File "/usr/local/lib/python3.9/site-packages/flask/app.py", line 463, in raise_routing_exception
    raise request.routing_exception  # type: ignore[misc]
  File "/usr/local/lib/python3.9/site-packages/flask/ctx.py", line 362, in match_request
    result = self.url_adapter.match(return_rule=True)  # type: ignore
  File "/usr/local/lib/python3.9/site-packages/werkzeug/routing/map.py", line 629, in match
    raise NotFound() from None
werkzeug.exceptions.NotFound: 404 Not Found: The requested URL was not found on the server. If you entered the URL manually please check your spelling and try again.
2024-10-18 14:26:08,826 ERROR Error: 405 Method Not Allowed: The method is not allowed for the requested URL.
Traceback (most recent call last):
  File "/usr/local/lib/python3.9/site-packages/flask/app.py", line 880, in full_dispatch_request
    rv = self.dispatch_request()
  File "/usr/local/lib/python3.9/site-packages/flask/app.py", line 854, in dispatch_request
    self.raise_routing_exception(req)
  File "/usr/local/lib/python3.9/site-packages/flask/app.py", line 463, in raise_routing_exception
    raise request.routing_exception  # type: ignore[misc]
  File "/usr/local/lib/python3.9/site-packages/flask/ctx.py", line 362, in match_request
    result = self.url_adapter.match(return_rule=True)  # type: ignore
  File "/usr/local/lib/python3.9/site-packages/werkzeug/routing/map.py", line 624, in match
    raise MethodNotAllowed(valid_methods=list(e.have_match_for)) from None
werkzeug.exceptions.MethodNotAllowed: 405 Method Not Allowed: The method is not allowed for the requested URL.
2024-10-18 14:26:08,877 ERROR Error: 404 Not Found: The requested URL was not found on the server. If you entered the URL manually please check your spelling and try again.
Traceback (most recent call last):
  File "/usr/local/lib/python3.9/site-packages/flask/app.py", line 880, in full_dispatch_request
    rv = self.dispatch_request()
  File "/usr/local/lib/python3.9/site-packages/flask/app.py", line 854, in dispatch_request
    self.raise_routing_exception(req)
  File "/usr/local/lib/python3.9/site-packages/flask/app.py", line 463, in raise_routing_exception
    raise request.routing_exception  # type: ignore[misc]
  File "/usr/local/lib/python3.9/site-packages/flask/ctx.py", line 362, in match_request
    result = self.url_adapter.match(return_rule=True)  # type: ignore
  File "/usr/local/lib/python3.9/site-packages/werkzeug/routing/map.py", line 629, in match
    raise NotFound() from None
werkzeug.exceptions.NotFound: 404 Not Found: The requested URL was not found on the server. If you entered the URL manually please check your spelling and try again.
2024-10-18 14:28:12,377 ERROR Error fetching data: 2003 (HY000): Can't connect to MySQL server on 'mysql-compose-container:3306' (111)
Traceback (most recent call last):
  File "/usr/local/lib/python3.9/site-packages/mysql/connector/connection_cext.py", line 335, in _open_connection
    self._cmysql.connect(**cnx_kwargs)
_mysql_connector.MySQLInterfaceError: Can't connect to MySQL server on 'mysql-compose-container:3306' (111)

The above exception was the direct cause of the following exception:

Traceback (most recent call last):
  File "/app/app.py", line 51, in get_data
    connection = mysql.connector.connect(**db_config)
  File "/usr/local/lib/python3.9/site-packages/mysql/connector/pooling.py", line 322, in connect
    return CMySQLConnection(*args, **kwargs)
  File "/usr/local/lib/python3.9/site-packages/mysql/connector/connection_cext.py", line 151, in __init__
    self.connect(**kwargs)
  File "/usr/local/lib/python3.9/site-packages/mysql/connector/abstracts.py", line 1426, in connect
    self._open_connection()
  File "/usr/local/lib/python3.9/site-packages/mysql/connector/connection_cext.py", line 340, in _open_connection
    raise get_mysql_exception(
mysql.connector.errors.DatabaseError: 2003 (HY000): Can't connect to MySQL server on 'mysql-compose-container:3306' (111)
2024-11-03 11:26:23,433 ERROR Error fetching data: 2003 (HY000): Can't connect to MySQL server on 'localhost:3306' (111)
Traceback (most recent call last):
  File "/usr/local/lib/python3.9/site-packages/mysql/connector/connection_cext.py", line 335, in _open_connection
    self._cmysql.connect(**cnx_kwargs)
_mysql_connector.MySQLInterfaceError: Can't connect to MySQL server on 'localhost:3306' (111)

The above exception was the direct cause of the following exception:

Traceback (most recent call last):
  File "/app/app.py", line 192, in get_data
    connection = mysql.connector.connect(**db_config)
  File "/usr/local/lib/python3.9/site-packages/mysql/connector/pooling.py", line 322, in connect
    return CMySQLConnection(*args, **kwargs)
  File "/usr/local/lib/python3.9/site-packages/mysql/connector/connection_cext.py", line 151, in __init__
    self.connect(**kwargs)
  File "/usr/local/lib/python3.9/site-packages/mysql/connector/abstracts.py", line 1426, in connect
    self._open_connection()
  File "/usr/local/lib/python3.9/site-packages/mysql/connector/connection_cext.py", line 340, in _open_connection
    raise get_mysql_exception(
mysql.connector.errors.DatabaseError: 2003 (HY000): Can't connect to MySQL server on 'localhost:3306' (111)
2024-11-03 11:26:30,464 ERROR Error fetching data: 2003 (HY000): Can't connect to MySQL server on 'localhost:3306' (111)
Traceback (most recent call last):
  File "/usr/local/lib/python3.9/site-packages/mysql/connector/connection_cext.py", line 335, in _open_connection
    self._cmysql.connect(**cnx_kwargs)
_mysql_connector.MySQLInterfaceError: Can't connect to MySQL server on 'localhost:3306' (111)

The above exception was the direct cause of the following exception:

Traceback (most recent call last):
  File "/app/app.py", line 192, in get_data
    connection = mysql.connector.connect(**db_config)
  File "/usr/local/lib/python3.9/site-packages/mysql/connector/pooling.py", line 322, in connect
    return CMySQLConnection(*args, **kwargs)
  File "/usr/local/lib/python3.9/site-packages/mysql/connector/connection_cext.py", line 151, in __init__
    self.connect(**kwargs)
  File "/usr/local/lib/python3.9/site-packages/mysql/connector/abstracts.py", line 1426, in connect
    self._open_connection()
  File "/usr/local/lib/python3.9/site-packages/mysql/connector/connection_cext.py", line 340, in _open_connection
    raise get_mysql_exception(
mysql.connector.errors.DatabaseError: 2003 (HY000): Can't connect to MySQL server on 'localhost:3306' (111)
2024-11-03 11:26:31,393 ERROR Error fetching data: 2003 (HY000): Can't connect to MySQL server on 'localhost:3306' (111)
Traceback (most recent call last):
  File "/usr/local/lib/python3.9/site-packages/mysql/connector/connection_cext.py", line 335, in _open_connection
    self._cmysql.connect(**cnx_kwargs)
_mysql_connector.MySQLInterfaceError: Can't connect to MySQL server on 'localhost:3306' (111)

The above exception was the direct cause of the following exception:

Traceback (most recent call last):
  File "/app/app.py", line 192, in get_data
    connection = mysql.connector.connect(**db_config)
  File "/usr/local/lib/python3.9/site-packages/mysql/connector/pooling.py", line 322, in connect
    return CMySQLConnection(*args, **kwargs)
  File "/usr/local/lib/python3.9/site-packages/mysql/connector/connection_cext.py", line 151, in __init__
    self.connect(**kwargs)
  File "/usr/local/lib/python3.9/site-packages/mysql/connector/abstracts.py", line 1426, in connect
    self._open_connection()
  File "/usr/local/lib/python3.9/site-packages/mysql/connector/connection_cext.py", line 340, in _open_connection
    raise get_mysql_exception(
mysql.connector.errors.DatabaseError: 2003 (HY000): Can't connect to MySQL server on 'localhost:3306' (111)
2024-11-03 11:26:35,445 ERROR Error fetching data: 2003 (HY000): Can't connect to MySQL server on 'localhost:3306' (111)
Traceback (most recent call last):
  File "/usr/local/lib/python3.9/site-packages/mysql/connector/connection_cext.py", line 335, in _open_connection
    self._cmysql.connect(**cnx_kwargs)
_mysql_connector.MySQLInterfaceError: Can't connect to MySQL server on 'localhost:3306' (111)

The above exception was the direct cause of the following exception:

Traceback (most recent call last):
  File "/app/app.py", line 192, in get_data
    connection = mysql.connector.connect(**db_config)
  File "/usr/local/lib/python3.9/site-packages/mysql/connector/pooling.py", line 322, in connect
    return CMySQLConnection(*args, **kwargs)
  File "/usr/local/lib/python3.9/site-packages/mysql/connector/connection_cext.py", line 151, in __init__
    self.connect(**kwargs)
  File "/usr/local/lib/python3.9/site-packages/mysql/connector/abstracts.py", line 1426, in connect
    self._open_connection()
  File "/usr/local/lib/python3.9/site-packages/mysql/connector/connection_cext.py", line 340, in _open_connection
    raise get_mysql_exception(
mysql.connector.errors.DatabaseError: 2003 (HY000): Can't connect to MySQL server on 'localhost:3306' (111)
2024-11-03 11:26:36,471 ERROR Error fetching data: 2003 (HY000): Can't connect to MySQL server on 'localhost:3306' (111)
Traceback (most recent call last):
  File "/usr/local/lib/python3.9/site-packages/mysql/connector/connection_cext.py", line 335, in _open_connection
    self._cmysql.connect(**cnx_kwargs)
_mysql_connector.MySQLInterfaceError: Can't connect to MySQL server on 'localhost:3306' (111)

The above exception was the direct cause of the following exception:

Traceback (most recent call last):
  File "/app/app.py", line 192, in get_data
    connection = mysql.connector.connect(**db_config)
  File "/usr/local/lib/python3.9/site-packages/mysql/connector/pooling.py", line 322, in connect
    return CMySQLConnection(*args, **kwargs)
  File "/usr/local/lib/python3.9/site-packages/mysql/connector/connection_cext.py", line 151, in __init__
    self.connect(**kwargs)
  File "/usr/local/lib/python3.9/site-packages/mysql/connector/abstracts.py", line 1426, in connect
    self._open_connection()
  File "/usr/local/lib/python3.9/site-packages/mysql/connector/connection_cext.py", line 340, in _open_connection
    raise get_mysql_exception(
mysql.connector.errors.DatabaseError: 2003 (HY000): Can't connect to MySQL server on 'localhost:3306' (111)
2024-11-03 11:26:39,703 ERROR Error fetching data: 2003 (HY000): Can't connect to MySQL server on 'localhost:3306' (111)
Traceback (most recent call last):
  File "/usr/local/lib/python3.9/site-packages/mysql/connector/connection_cext.py", line 335, in _open_connection
    self._cmysql.connect(**cnx_kwargs)
_mysql_connector.MySQLInterfaceError: Can't connect to MySQL server on 'localhost:3306' (111)

The above exception was the direct cause of the following exception:

Traceback (most recent call last):
  File "/app/app.py", line 192, in get_data
    connection = mysql.connector.connect(**db_config)
  File "/usr/local/lib/python3.9/site-packages/mysql/connector/pooling.py", line 322, in connect
    return CMySQLConnection(*args, **kwargs)
  File "/usr/local/lib/python3.9/site-packages/mysql/connector/connection_cext.py", line 151, in __init__
    self.connect(**kwargs)
  File "/usr/local/lib/python3.9/site-packages/mysql/connector/abstracts.py", line 1426, in connect
    self._open_connection()
  File "/usr/local/lib/python3.9/site-packages/mysql/connector/connection_cext.py", line 340, in _open_connection
    raise get_mysql_exception(
mysql.connector.errors.DatabaseError: 2003 (HY000): Can't connect to MySQL server on 'localhost:3306' (111)
2024-11-03 11:26:46,968 ERROR Error logging in user: 2003 (HY000): Can't connect to MySQL server on 'localhost:3306' (111)
Traceback (most recent call last):
  File "/usr/local/lib/python3.9/site-packages/mysql/connector/connection_cext.py", line 335, in _open_connection
    self._cmysql.connect(**cnx_kwargs)
_mysql_connector.MySQLInterfaceError: Can't connect to MySQL server on 'localhost:3306' (111)

The above exception was the direct cause of the following exception:

Traceback (most recent call last):
  File "/app/app.py", line 281, in login_user
    connection = mysql.connector.connect(**db_config)
  File "/usr/local/lib/python3.9/site-packages/mysql/connector/pooling.py", line 322, in connect
    return CMySQLConnection(*args, **kwargs)
  File "/usr/local/lib/python3.9/site-packages/mysql/connector/connection_cext.py", line 151, in __init__
    self.connect(**kwargs)
  File "/usr/local/lib/python3.9/site-packages/mysql/connector/abstracts.py", line 1426, in connect
    self._open_connection()
  File "/usr/local/lib/python3.9/site-packages/mysql/connector/connection_cext.py", line 340, in _open_connection
    raise get_mysql_exception(
mysql.connector.errors.DatabaseError: 2003 (HY000): Can't connect to MySQL server on 'localhost:3306' (111)
2024-11-03 11:32:19,758 ERROR Error fetching data: 2003 (HY000): Can't connect to MySQL server on 'localhost:3306' (111)
Traceback (most recent call last):
  File "/usr/local/lib/python3.9/site-packages/mysql/connector/connection_cext.py", line 335, in _open_connection
    self._cmysql.connect(**cnx_kwargs)
_mysql_connector.MySQLInterfaceError: Can't connect to MySQL server on 'localhost:3306' (111)

The above exception was the direct cause of the following exception:

Traceback (most recent call last):
  File "/app/app.py", line 193, in get_data
    connection = mysql.connector.connect(**db_config)
  File "/usr/local/lib/python3.9/site-packages/mysql/connector/pooling.py", line 322, in connect
    return CMySQLConnection(*args, **kwargs)
  File "/usr/local/lib/python3.9/site-packages/mysql/connector/connection_cext.py", line 151, in __init__
    self.connect(**kwargs)
  File "/usr/local/lib/python3.9/site-packages/mysql/connector/abstracts.py", line 1426, in connect
    self._open_connection()
  File "/usr/local/lib/python3.9/site-packages/mysql/connector/connection_cext.py", line 340, in _open_connection
    raise get_mysql_exception(
mysql.connector.errors.DatabaseError: 2003 (HY000): Can't connect to MySQL server on 'localhost:3306' (111)
2024-11-03 11:32:20,517 ERROR Error fetching data: 2003 (HY000): Can't connect to MySQL server on 'localhost:3306' (111)
Traceback (most recent call last):
  File "/usr/local/lib/python3.9/site-packages/mysql/connector/connection_cext.py", line 335, in _open_connection
    self._cmysql.connect(**cnx_kwargs)
_mysql_connector.MySQLInterfaceError: Can't connect to MySQL server on 'localhost:3306' (111)

The above exception was the direct cause of the following exception:

Traceback (most recent call last):
  File "/app/app.py", line 193, in get_data
    connection = mysql.connector.connect(**db_config)
  File "/usr/local/lib/python3.9/site-packages/mysql/connector/pooling.py", line 322, in connect
    return CMySQLConnection(*args, **kwargs)
  File "/usr/local/lib/python3.9/site-packages/mysql/connector/connection_cext.py", line 151, in __init__
    self.connect(**kwargs)
  File "/usr/local/lib/python3.9/site-packages/mysql/connector/abstracts.py", line 1426, in connect
    self._open_connection()
  File "/usr/local/lib/python3.9/site-packages/mysql/connector/connection_cext.py", line 340, in _open_connection
    raise get_mysql_exception(
mysql.connector.errors.DatabaseError: 2003 (HY000): Can't connect to MySQL server on 'localhost:3306' (111)
2024-11-03 11:32:35,291 ERROR Error fetching data: 2003 (HY000): Can't connect to MySQL server on 'localhost:3306' (111)
Traceback (most recent call last):
  File "/usr/local/lib/python3.9/site-packages/mysql/connector/connection_cext.py", line 335, in _open_connection
    self._cmysql.connect(**cnx_kwargs)
_mysql_connector.MySQLInterfaceError: Can't connect to MySQL server on 'localhost:3306' (111)

The above exception was the direct cause of the following exception:

Traceback (most recent call last):
  File "/app/app.py", line 193, in get_data
    connection = mysql.connector.connect(**db_config)
  File "/usr/local/lib/python3.9/site-packages/mysql/connector/pooling.py", line 322, in connect
    return CMySQLConnection(*args, **kwargs)
  File "/usr/local/lib/python3.9/site-packages/mysql/connector/connection_cext.py", line 151, in __init__
    self.connect(**kwargs)
  File "/usr/local/lib/python3.9/site-packages/mysql/connector/abstracts.py", line 1426, in connect
    self._open_connection()
  File "/usr/local/lib/python3.9/site-packages/mysql/connector/connection_cext.py", line 340, in _open_connection
    raise get_mysql_exception(
mysql.connector.errors.DatabaseError: 2003 (HY000): Can't connect to MySQL server on 'localhost:3306' (111)
2024-11-03 11:33:56,310 ERROR Error fetching data: 2003 (HY000): Can't connect to MySQL server on 'localhost:3306' (111)
Traceback (most recent call last):
  File "/usr/local/lib/python3.9/site-packages/mysql/connector/connection_cext.py", line 335, in _open_connection
    self._cmysql.connect(**cnx_kwargs)
_mysql_connector.MySQLInterfaceError: Can't connect to MySQL server on 'localhost:3306' (111)

The above exception was the direct cause of the following exception:

Traceback (most recent call last):
  File "/app/app.py", line 193, in get_data
    connection = mysql.connector.connect(**db_config)
  File "/usr/local/lib/python3.9/site-packages/mysql/connector/pooling.py", line 322, in connect
    return CMySQLConnection(*args, **kwargs)
  File "/usr/local/lib/python3.9/site-packages/mysql/connector/connection_cext.py", line 151, in __init__
    self.connect(**kwargs)
  File "/usr/local/lib/python3.9/site-packages/mysql/connector/abstracts.py", line 1426, in connect
    self._open_connection()
  File "/usr/local/lib/python3.9/site-packages/mysql/connector/connection_cext.py", line 340, in _open_connection
    raise get_mysql_exception(
mysql.connector.errors.DatabaseError: 2003 (HY000): Can't connect to MySQL server on 'localhost:3306' (111)
2024-11-03 11:33:57,281 ERROR Error fetching data: 2003 (HY000): Can't connect to MySQL server on 'localhost:3306' (111)
Traceback (most recent call last):
  File "/usr/local/lib/python3.9/site-packages/mysql/connector/connection_cext.py", line 335, in _open_connection
    self._cmysql.connect(**cnx_kwargs)
_mysql_connector.MySQLInterfaceError: Can't connect to MySQL server on 'localhost:3306' (111)

The above exception was the direct cause of the following exception:

Traceback (most recent call last):
  File "/app/app.py", line 193, in get_data
    connection = mysql.connector.connect(**db_config)
  File "/usr/local/lib/python3.9/site-packages/mysql/connector/pooling.py", line 322, in connect
    return CMySQLConnection(*args, **kwargs)
  File "/usr/local/lib/python3.9/site-packages/mysql/connector/connection_cext.py", line 151, in __init__
    self.connect(**kwargs)
  File "/usr/local/lib/python3.9/site-packages/mysql/connector/abstracts.py", line 1426, in connect
    self._open_connection()
  File "/usr/local/lib/python3.9/site-packages/mysql/connector/connection_cext.py", line 340, in _open_connection
    raise get_mysql_exception(
mysql.connector.errors.DatabaseError: 2003 (HY000): Can't connect to MySQL server on 'localhost:3306' (111)
2024-11-03 11:33:57,681 ERROR Error fetching data: 2003 (HY000): Can't connect to MySQL server on 'localhost:3306' (111)
Traceback (most recent call last):
  File "/usr/local/lib/python3.9/site-packages/mysql/connector/connection_cext.py", line 335, in _open_connection
    self._cmysql.connect(**cnx_kwargs)
_mysql_connector.MySQLInterfaceError: Can't connect to MySQL server on 'localhost:3306' (111)

The above exception was the direct cause of the following exception:

Traceback (most recent call last):
  File "/app/app.py", line 193, in get_data
    connection = mysql.connector.connect(**db_config)
  File "/usr/local/lib/python3.9/site-packages/mysql/connector/pooling.py", line 322, in connect
    return CMySQLConnection(*args, **kwargs)
  File "/usr/local/lib/python3.9/site-packages/mysql/connector/connection_cext.py", line 151, in __init__
    self.connect(**kwargs)
  File "/usr/local/lib/python3.9/site-packages/mysql/connector/abstracts.py", line 1426, in connect
    self._open_connection()
  File "/usr/local/lib/python3.9/site-packages/mysql/connector/connection_cext.py", line 340, in _open_connection
    raise get_mysql_exception(
mysql.connector.errors.DatabaseError: 2003 (HY000): Can't connect to MySQL server on 'localhost:3306' (111)
2024-11-03 11:33:57,851 ERROR Error fetching data: 2003 (HY000): Can't connect to MySQL server on 'localhost:3306' (111)
Traceback (most recent call last):
  File "/usr/local/lib/python3.9/site-packages/mysql/connector/connection_cext.py", line 335, in _open_connection
    self._cmysql.connect(**cnx_kwargs)
_mysql_connector.MySQLInterfaceError: Can't connect to MySQL server on 'localhost:3306' (111)

The above exception was the direct cause of the following exception:

Traceback (most recent call last):
  File "/app/app.py", line 193, in get_data
    connection = mysql.connector.connect(**db_config)
  File "/usr/local/lib/python3.9/site-packages/mysql/connector/pooling.py", line 322, in connect
    return CMySQLConnection(*args, **kwargs)
  File "/usr/local/lib/python3.9/site-packages/mysql/connector/connection_cext.py", line 151, in __init__
    self.connect(**kwargs)
  File "/usr/local/lib/python3.9/site-packages/mysql/connector/abstracts.py", line 1426, in connect
    self._open_connection()
  File "/usr/local/lib/python3.9/site-packages/mysql/connector/connection_cext.py", line 340, in _open_connection
    raise get_mysql_exception(
mysql.connector.errors.DatabaseError: 2003 (HY000): Can't connect to MySQL server on 'localhost:3306' (111)
2024-11-03 11:33:58,004 ERROR Error fetching data: 2003 (HY000): Can't connect to MySQL server on 'localhost:3306' (111)
Traceback (most recent call last):
  File "/usr/local/lib/python3.9/site-packages/mysql/connector/connection_cext.py", line 335, in _open_connection
    self._cmysql.connect(**cnx_kwargs)
_mysql_connector.MySQLInterfaceError: Can't connect to MySQL server on 'localhost:3306' (111)

The above exception was the direct cause of the following exception:

Traceback (most recent call last):
  File "/app/app.py", line 193, in get_data
    connection = mysql.connector.connect(**db_config)
  File "/usr/local/lib/python3.9/site-packages/mysql/connector/pooling.py", line 322, in connect
    return CMySQLConnection(*args, **kwargs)
  File "/usr/local/lib/python3.9/site-packages/mysql/connector/connection_cext.py", line 151, in __init__
    self.connect(**kwargs)
  File "/usr/local/lib/python3.9/site-packages/mysql/connector/abstracts.py", line 1426, in connect
    self._open_connection()
  File "/usr/local/lib/python3.9/site-packages/mysql/connector/connection_cext.py", line 340, in _open_connection
    raise get_mysql_exception(
mysql.connector.errors.DatabaseError: 2003 (HY000): Can't connect to MySQL server on 'localhost:3306' (111)
2024-11-03 11:33:58,187 ERROR Error fetching data: 2003 (HY000): Can't connect to MySQL server on 'localhost:3306' (111)
Traceback (most recent call last):
  File "/usr/local/lib/python3.9/site-packages/mysql/connector/connection_cext.py", line 335, in _open_connection
    self._cmysql.connect(**cnx_kwargs)
_mysql_connector.MySQLInterfaceError: Can't connect to MySQL server on 'localhost:3306' (111)

The above exception was the direct cause of the following exception:

Traceback (most recent call last):
  File "/app/app.py", line 193, in get_data
    connection = mysql.connector.connect(**db_config)
  File "/usr/local/lib/python3.9/site-packages/mysql/connector/pooling.py", line 322, in connect
    return CMySQLConnection(*args, **kwargs)
  File "/usr/local/lib/python3.9/site-packages/mysql/connector/connection_cext.py", line 151, in __init__
    self.connect(**kwargs)
  File "/usr/local/lib/python3.9/site-packages/mysql/connector/abstracts.py", line 1426, in connect
    self._open_connection()
  File "/usr/local/lib/python3.9/site-packages/mysql/connector/connection_cext.py", line 340, in _open_connection
    raise get_mysql_exception(
mysql.connector.errors.DatabaseError: 2003 (HY000): Can't connect to MySQL server on 'localhost:3306' (111)
2024-11-03 11:33:58,329 ERROR Error fetching data: 2003 (HY000): Can't connect to MySQL server on 'localhost:3306' (111)
Traceback (most recent call last):
  File "/usr/local/lib/python3.9/site-packages/mysql/connector/connection_cext.py", line 335, in _open_connection
    self._cmysql.connect(**cnx_kwargs)
_mysql_connector.MySQLInterfaceError: Can't connect to MySQL server on 'localhost:3306' (111)

The above exception was the direct cause of the following exception:

Traceback (most recent call last):
  File "/app/app.py", line 193, in get_data
    connection = mysql.connector.connect(**db_config)
  File "/usr/local/lib/python3.9/site-packages/mysql/connector/pooling.py", line 322, in connect
    return CMySQLConnection(*args, **kwargs)
  File "/usr/local/lib/python3.9/site-packages/mysql/connector/connection_cext.py", line 151, in __init__
    self.connect(**kwargs)
  File "/usr/local/lib/python3.9/site-packages/mysql/connector/abstracts.py", line 1426, in connect
    self._open_connection()
  File "/usr/local/lib/python3.9/site-packages/mysql/connector/connection_cext.py", line 340, in _open_connection
    raise get_mysql_exception(
mysql.connector.errors.DatabaseError: 2003 (HY000): Can't connect to MySQL server on 'localhost:3306' (111)
2024-11-03 11:33:58,476 ERROR Error fetching data: 2003 (HY000): Can't connect to MySQL server on 'localhost:3306' (111)
Traceback (most recent call last):
  File "/usr/local/lib/python3.9/site-packages/mysql/connector/connection_cext.py", line 335, in _open_connection
    self._cmysql.connect(**cnx_kwargs)
_mysql_connector.MySQLInterfaceError: Can't connect to MySQL server on 'localhost:3306' (111)

The above exception was the direct cause of the following exception:

Traceback (most recent call last):
  File "/app/app.py", line 193, in get_data
    connection = mysql.connector.connect(**db_config)
  File "/usr/local/lib/python3.9/site-packages/mysql/connector/pooling.py", line 322, in connect
    return CMySQLConnection(*args, **kwargs)
  File "/usr/local/lib/python3.9/site-packages/mysql/connector/connection_cext.py", line 151, in __init__
    self.connect(**kwargs)
  File "/usr/local/lib/python3.9/site-packages/mysql/connector/abstracts.py", line 1426, in connect
    self._open_connection()
  File "/usr/local/lib/python3.9/site-packages/mysql/connector/connection_cext.py", line 340, in _open_connection
    raise get_mysql_exception(
mysql.connector.errors.DatabaseError: 2003 (HY000): Can't connect to MySQL server on 'localhost:3306' (111)
2024-11-03 11:33:58,637 ERROR Error fetching data: 2003 (HY000): Can't connect to MySQL server on 'localhost:3306' (111)
Traceback (most recent call last):
  File "/usr/local/lib/python3.9/site-packages/mysql/connector/connection_cext.py", line 335, in _open_connection
    self._cmysql.connect(**cnx_kwargs)
_mysql_connector.MySQLInterfaceError: Can't connect to MySQL server on 'localhost:3306' (111)

The above exception was the direct cause of the following exception:

Traceback (most recent call last):
  File "/app/app.py", line 193, in get_data
    connection = mysql.connector.connect(**db_config)
  File "/usr/local/lib/python3.9/site-packages/mysql/connector/pooling.py", line 322, in connect
    return CMySQLConnection(*args, **kwargs)
  File "/usr/local/lib/python3.9/site-packages/mysql/connector/connection_cext.py", line 151, in __init__
    self.connect(**kwargs)
  File "/usr/local/lib/python3.9/site-packages/mysql/connector/abstracts.py", line 1426, in connect
    self._open_connection()
  File "/usr/local/lib/python3.9/site-packages/mysql/connector/connection_cext.py", line 340, in _open_connection
    raise get_mysql_exception(
mysql.connector.errors.DatabaseError: 2003 (HY000): Can't connect to MySQL server on 'localhost:3306' (111)
2024-11-03 11:33:58,795 ERROR Error fetching data: 2003 (HY000): Can't connect to MySQL server on 'localhost:3306' (111)
Traceback (most recent call last):
  File "/usr/local/lib/python3.9/site-packages/mysql/connector/connection_cext.py", line 335, in _open_connection
    self._cmysql.connect(**cnx_kwargs)
_mysql_connector.MySQLInterfaceError: Can't connect to MySQL server on 'localhost:3306' (111)

The above exception was the direct cause of the following exception:

Traceback (most recent call last):
  File "/app/app.py", line 193, in get_data
    connection = mysql.connector.connect(**db_config)
  File "/usr/local/lib/python3.9/site-packages/mysql/connector/pooling.py", line 322, in connect
    return CMySQLConnection(*args, **kwargs)
  File "/usr/local/lib/python3.9/site-packages/mysql/connector/connection_cext.py", line 151, in __init__
    self.connect(**kwargs)
  File "/usr/local/lib/python3.9/site-packages/mysql/connector/abstracts.py", line 1426, in connect
    self._open_connection()
  File "/usr/local/lib/python3.9/site-packages/mysql/connector/connection_cext.py", line 340, in _open_connection
    raise get_mysql_exception(
mysql.connector.errors.DatabaseError: 2003 (HY000): Can't connect to MySQL server on 'localhost:3306' (111)
2024-11-03 11:33:58,949 ERROR Error fetching data: 2003 (HY000): Can't connect to MySQL server on 'localhost:3306' (111)
Traceback (most recent call last):
  File "/usr/local/lib/python3.9/site-packages/mysql/connector/connection_cext.py", line 335, in _open_connection
    self._cmysql.connect(**cnx_kwargs)
_mysql_connector.MySQLInterfaceError: Can't connect to MySQL server on 'localhost:3306' (111)

The above exception was the direct cause of the following exception:

Traceback (most recent call last):
  File "/app/app.py", line 193, in get_data
    connection = mysql.connector.connect(**db_config)
  File "/usr/local/lib/python3.9/site-packages/mysql/connector/pooling.py", line 322, in connect
    return CMySQLConnection(*args, **kwargs)
  File "/usr/local/lib/python3.9/site-packages/mysql/connector/connection_cext.py", line 151, in __init__
    self.connect(**kwargs)
  File "/usr/local/lib/python3.9/site-packages/mysql/connector/abstracts.py", line 1426, in connect
    self._open_connection()
  File "/usr/local/lib/python3.9/site-packages/mysql/connector/connection_cext.py", line 340, in _open_connection
    raise get_mysql_exception(
mysql.connector.errors.DatabaseError: 2003 (HY000): Can't connect to MySQL server on 'localhost:3306' (111)
2024-11-03 11:33:59,111 ERROR Error fetching data: 2003 (HY000): Can't connect to MySQL server on 'localhost:3306' (111)
Traceback (most recent call last):
  File "/usr/local/lib/python3.9/site-packages/mysql/connector/connection_cext.py", line 335, in _open_connection
    self._cmysql.connect(**cnx_kwargs)
_mysql_connector.MySQLInterfaceError: Can't connect to MySQL server on 'localhost:3306' (111)

The above exception was the direct cause of the following exception:

Traceback (most recent call last):
  File "/app/app.py", line 193, in get_data
    connection = mysql.connector.connect(**db_config)
  File "/usr/local/lib/python3.9/site-packages/mysql/connector/pooling.py", line 322, in connect
    return CMySQLConnection(*args, **kwargs)
  File "/usr/local/lib/python3.9/site-packages/mysql/connector/connection_cext.py", line 151, in __init__
    self.connect(**kwargs)
  File "/usr/local/lib/python3.9/site-packages/mysql/connector/abstracts.py", line 1426, in connect
    self._open_connection()
  File "/usr/local/lib/python3.9/site-packages/mysql/connector/connection_cext.py", line 340, in _open_connection
    raise get_mysql_exception(
mysql.connector.errors.DatabaseError: 2003 (HY000): Can't connect to MySQL server on 'localhost:3306' (111)
2024-11-03 11:33:59,269 ERROR Error fetching data: 2003 (HY000): Can't connect to MySQL server on 'localhost:3306' (111)
Traceback (most recent call last):
  File "/usr/local/lib/python3.9/site-packages/mysql/connector/connection_cext.py", line 335, in _open_connection
    self._cmysql.connect(**cnx_kwargs)
_mysql_connector.MySQLInterfaceError: Can't connect to MySQL server on 'localhost:3306' (111)

The above exception was the direct cause of the following exception:

Traceback (most recent call last):
  File "/app/app.py", line 193, in get_data
    connection = mysql.connector.connect(**db_config)
  File "/usr/local/lib/python3.9/site-packages/mysql/connector/pooling.py", line 322, in connect
    return CMySQLConnection(*args, **kwargs)
  File "/usr/local/lib/python3.9/site-packages/mysql/connector/connection_cext.py", line 151, in __init__
    self.connect(**kwargs)
  File "/usr/local/lib/python3.9/site-packages/mysql/connector/abstracts.py", line 1426, in connect
    self._open_connection()
  File "/usr/local/lib/python3.9/site-packages/mysql/connector/connection_cext.py", line 340, in _open_connection
    raise get_mysql_exception(
mysql.connector.errors.DatabaseError: 2003 (HY000): Can't connect to MySQL server on 'localhost:3306' (111)
2024-11-03 11:33:59,416 ERROR Error fetching data: 2003 (HY000): Can't connect to MySQL server on 'localhost:3306' (111)
Traceback (most recent call last):
  File "/usr/local/lib/python3.9/site-packages/mysql/connector/connection_cext.py", line 335, in _open_connection
    self._cmysql.connect(**cnx_kwargs)
_mysql_connector.MySQLInterfaceError: Can't connect to MySQL server on 'localhost:3306' (111)

The above exception was the direct cause of the following exception:

Traceback (most recent call last):
  File "/app/app.py", line 193, in get_data
    connection = mysql.connector.connect(**db_config)
  File "/usr/local/lib/python3.9/site-packages/mysql/connector/pooling.py", line 322, in connect
    return CMySQLConnection(*args, **kwargs)
  File "/usr/local/lib/python3.9/site-packages/mysql/connector/connection_cext.py", line 151, in __init__
    self.connect(**kwargs)
  File "/usr/local/lib/python3.9/site-packages/mysql/connector/abstracts.py", line 1426, in connect
    self._open_connection()
  File "/usr/local/lib/python3.9/site-packages/mysql/connector/connection_cext.py", line 340, in _open_connection
    raise get_mysql_exception(
mysql.connector.errors.DatabaseError: 2003 (HY000): Can't connect to MySQL server on 'localhost:3306' (111)
2024-11-03 11:33:59,564 ERROR Error fetching data: 2003 (HY000): Can't connect to MySQL server on 'localhost:3306' (111)
Traceback (most recent call last):
  File "/usr/local/lib/python3.9/site-packages/mysql/connector/connection_cext.py", line 335, in _open_connection
    self._cmysql.connect(**cnx_kwargs)
_mysql_connector.MySQLInterfaceError: Can't connect to MySQL server on 'localhost:3306' (111)

The above exception was the direct cause of the following exception:

Traceback (most recent call last):
  File "/app/app.py", line 193, in get_data
    connection = mysql.connector.connect(**db_config)
  File "/usr/local/lib/python3.9/site-packages/mysql/connector/pooling.py", line 322, in connect
    return CMySQLConnection(*args, **kwargs)
  File "/usr/local/lib/python3.9/site-packages/mysql/connector/connection_cext.py", line 151, in __init__
    self.connect(**kwargs)
  File "/usr/local/lib/python3.9/site-packages/mysql/connector/abstracts.py", line 1426, in connect
    self._open_connection()
  File "/usr/local/lib/python3.9/site-packages/mysql/connector/connection_cext.py", line 340, in _open_connection
    raise get_mysql_exception(
mysql.connector.errors.DatabaseError: 2003 (HY000): Can't connect to MySQL server on 'localhost:3306' (111)
2024-11-03 11:33:59,711 ERROR Error fetching data: 2003 (HY000): Can't connect to MySQL server on 'localhost:3306' (111)
Traceback (most recent call last):
  File "/usr/local/lib/python3.9/site-packages/mysql/connector/connection_cext.py", line 335, in _open_connection
    self._cmysql.connect(**cnx_kwargs)
_mysql_connector.MySQLInterfaceError: Can't connect to MySQL server on 'localhost:3306' (111)

The above exception was the direct cause of the following exception:

Traceback (most recent call last):
  File "/app/app.py", line 193, in get_data
    connection = mysql.connector.connect(**db_config)
  File "/usr/local/lib/python3.9/site-packages/mysql/connector/pooling.py", line 322, in connect
    return CMySQLConnection(*args, **kwargs)
  File "/usr/local/lib/python3.9/site-packages/mysql/connector/connection_cext.py", line 151, in __init__
    self.connect(**kwargs)
  File "/usr/local/lib/python3.9/site-packages/mysql/connector/abstracts.py", line 1426, in connect
    self._open_connection()
  File "/usr/local/lib/python3.9/site-packages/mysql/connector/connection_cext.py", line 340, in _open_connection
    raise get_mysql_exception(
mysql.connector.errors.DatabaseError: 2003 (HY000): Can't connect to MySQL server on 'localhost:3306' (111)
2024-11-03 11:33:59,863 ERROR Error fetching data: 2003 (HY000): Can't connect to MySQL server on 'localhost:3306' (111)
Traceback (most recent call last):
  File "/usr/local/lib/python3.9/site-packages/mysql/connector/connection_cext.py", line 335, in _open_connection
    self._cmysql.connect(**cnx_kwargs)
_mysql_connector.MySQLInterfaceError: Can't connect to MySQL server on 'localhost:3306' (111)

The above exception was the direct cause of the following exception:

Traceback (most recent call last):
  File "/app/app.py", line 193, in get_data
    connection = mysql.connector.connect(**db_config)
  File "/usr/local/lib/python3.9/site-packages/mysql/connector/pooling.py", line 322, in connect
    return CMySQLConnection(*args, **kwargs)
  File "/usr/local/lib/python3.9/site-packages/mysql/connector/connection_cext.py", line 151, in __init__
    self.connect(**kwargs)
  File "/usr/local/lib/python3.9/site-packages/mysql/connector/abstracts.py", line 1426, in connect
    self._open_connection()
  File "/usr/local/lib/python3.9/site-packages/mysql/connector/connection_cext.py", line 340, in _open_connection
    raise get_mysql_exception(
mysql.connector.errors.DatabaseError: 2003 (HY000): Can't connect to MySQL server on 'localhost:3306' (111)
2024-11-03 11:34:00,023 ERROR Error fetching data: 2003 (HY000): Can't connect to MySQL server on 'localhost:3306' (111)
Traceback (most recent call last):
  File "/usr/local/lib/python3.9/site-packages/mysql/connector/connection_cext.py", line 335, in _open_connection
    self._cmysql.connect(**cnx_kwargs)
_mysql_connector.MySQLInterfaceError: Can't connect to MySQL server on 'localhost:3306' (111)

The above exception was the direct cause of the following exception:

Traceback (most recent call last):
  File "/app/app.py", line 193, in get_data
    connection = mysql.connector.connect(**db_config)
  File "/usr/local/lib/python3.9/site-packages/mysql/connector/pooling.py", line 322, in connect
    return CMySQLConnection(*args, **kwargs)
  File "/usr/local/lib/python3.9/site-packages/mysql/connector/connection_cext.py", line 151, in __init__
    self.connect(**kwargs)
  File "/usr/local/lib/python3.9/site-packages/mysql/connector/abstracts.py", line 1426, in connect
    self._open_connection()
  File "/usr/local/lib/python3.9/site-packages/mysql/connector/connection_cext.py", line 340, in _open_connection
    raise get_mysql_exception(
mysql.connector.errors.DatabaseError: 2003 (HY000): Can't connect to MySQL server on 'localhost:3306' (111)
2024-11-03 11:34:00,166 ERROR Error fetching data: 2003 (HY000): Can't connect to MySQL server on 'localhost:3306' (111)
Traceback (most recent call last):
  File "/usr/local/lib/python3.9/site-packages/mysql/connector/connection_cext.py", line 335, in _open_connection
    self._cmysql.connect(**cnx_kwargs)
_mysql_connector.MySQLInterfaceError: Can't connect to MySQL server on 'localhost:3306' (111)

The above exception was the direct cause of the following exception:

Traceback (most recent call last):
  File "/app/app.py", line 193, in get_data
    connection = mysql.connector.connect(**db_config)
  File "/usr/local/lib/python3.9/site-packages/mysql/connector/pooling.py", line 322, in connect
    return CMySQLConnection(*args, **kwargs)
  File "/usr/local/lib/python3.9/site-packages/mysql/connector/connection_cext.py", line 151, in __init__
    self.connect(**kwargs)
  File "/usr/local/lib/python3.9/site-packages/mysql/connector/abstracts.py", line 1426, in connect
    self._open_connection()
  File "/usr/local/lib/python3.9/site-packages/mysql/connector/connection_cext.py", line 340, in _open_connection
    raise get_mysql_exception(
mysql.connector.errors.DatabaseError: 2003 (HY000): Can't connect to MySQL server on 'localhost:3306' (111)
2024-11-03 11:34:00,302 ERROR Error fetching data: 2003 (HY000): Can't connect to MySQL server on 'localhost:3306' (111)
Traceback (most recent call last):
  File "/usr/local/lib/python3.9/site-packages/mysql/connector/connection_cext.py", line 335, in _open_connection
    self._cmysql.connect(**cnx_kwargs)
_mysql_connector.MySQLInterfaceError: Can't connect to MySQL server on 'localhost:3306' (111)

The above exception was the direct cause of the following exception:

Traceback (most recent call last):
  File "/app/app.py", line 193, in get_data
    connection = mysql.connector.connect(**db_config)
  File "/usr/local/lib/python3.9/site-packages/mysql/connector/pooling.py", line 322, in connect
    return CMySQLConnection(*args, **kwargs)
  File "/usr/local/lib/python3.9/site-packages/mysql/connector/connection_cext.py", line 151, in __init__
    self.connect(**kwargs)
  File "/usr/local/lib/python3.9/site-packages/mysql/connector/abstracts.py", line 1426, in connect
    self._open_connection()
  File "/usr/local/lib/python3.9/site-packages/mysql/connector/connection_cext.py", line 340, in _open_connection
    raise get_mysql_exception(
mysql.connector.errors.DatabaseError: 2003 (HY000): Can't connect to MySQL server on 'localhost:3306' (111)
2024-11-03 11:35:23,340 ERROR Error fetching data: 2003 (HY000): Can't connect to MySQL server on 'localhost:3306' (111)
Traceback (most recent call last):
  File "/usr/local/lib/python3.9/site-packages/mysql/connector/connection_cext.py", line 335, in _open_connection
    self._cmysql.connect(**cnx_kwargs)
_mysql_connector.MySQLInterfaceError: Can't connect to MySQL server on 'localhost:3306' (111)

The above exception was the direct cause of the following exception:

Traceback (most recent call last):
  File "/app/app.py", line 192, in get_data
    connection = mysql.connector.connect(**db_config)
  File "/usr/local/lib/python3.9/site-packages/mysql/connector/pooling.py", line 322, in connect
    return CMySQLConnection(*args, **kwargs)
  File "/usr/local/lib/python3.9/site-packages/mysql/connector/connection_cext.py", line 151, in __init__
    self.connect(**kwargs)
  File "/usr/local/lib/python3.9/site-packages/mysql/connector/abstracts.py", line 1426, in connect
    self._open_connection()
  File "/usr/local/lib/python3.9/site-packages/mysql/connector/connection_cext.py", line 340, in _open_connection
    raise get_mysql_exception(
mysql.connector.errors.DatabaseError: 2003 (HY000): Can't connect to MySQL server on 'localhost:3306' (111)
2024-11-03 11:35:24,241 ERROR Error fetching data: 2003 (HY000): Can't connect to MySQL server on 'localhost:3306' (111)
Traceback (most recent call last):
  File "/usr/local/lib/python3.9/site-packages/mysql/connector/connection_cext.py", line 335, in _open_connection
    self._cmysql.connect(**cnx_kwargs)
_mysql_connector.MySQLInterfaceError: Can't connect to MySQL server on 'localhost:3306' (111)

The above exception was the direct cause of the following exception:

Traceback (most recent call last):
  File "/app/app.py", line 192, in get_data
    connection = mysql.connector.connect(**db_config)
  File "/usr/local/lib/python3.9/site-packages/mysql/connector/pooling.py", line 322, in connect
    return CMySQLConnection(*args, **kwargs)
  File "/usr/local/lib/python3.9/site-packages/mysql/connector/connection_cext.py", line 151, in __init__
    self.connect(**kwargs)
  File "/usr/local/lib/python3.9/site-packages/mysql/connector/abstracts.py", line 1426, in connect
    self._open_connection()
  File "/usr/local/lib/python3.9/site-packages/mysql/connector/connection_cext.py", line 340, in _open_connection
    raise get_mysql_exception(
mysql.connector.errors.DatabaseError: 2003 (HY000): Can't connect to MySQL server on 'localhost:3306' (111)
2024-11-03 11:35:24,385 ERROR Error fetching data: 2003 (HY000): Can't connect to MySQL server on 'localhost:3306' (111)
Traceback (most recent call last):
  File "/usr/local/lib/python3.9/site-packages/mysql/connector/connection_cext.py", line 335, in _open_connection
    self._cmysql.connect(**cnx_kwargs)
_mysql_connector.MySQLInterfaceError: Can't connect to MySQL server on 'localhost:3306' (111)

The above exception was the direct cause of the following exception:

Traceback (most recent call last):
  File "/app/app.py", line 192, in get_data
    connection = mysql.connector.connect(**db_config)
  File "/usr/local/lib/python3.9/site-packages/mysql/connector/pooling.py", line 322, in connect
    return CMySQLConnection(*args, **kwargs)
  File "/usr/local/lib/python3.9/site-packages/mysql/connector/connection_cext.py", line 151, in __init__
    self.connect(**kwargs)
  File "/usr/local/lib/python3.9/site-packages/mysql/connector/abstracts.py", line 1426, in connect
    self._open_connection()
  File "/usr/local/lib/python3.9/site-packages/mysql/connector/connection_cext.py", line 340, in _open_connection
    raise get_mysql_exception(
mysql.connector.errors.DatabaseError: 2003 (HY000): Can't connect to MySQL server on 'localhost:3306' (111)
2024-11-03 11:35:24,547 ERROR Error fetching data: 2003 (HY000): Can't connect to MySQL server on 'localhost:3306' (111)
Traceback (most recent call last):
  File "/usr/local/lib/python3.9/site-packages/mysql/connector/connection_cext.py", line 335, in _open_connection
    self._cmysql.connect(**cnx_kwargs)
_mysql_connector.MySQLInterfaceError: Can't connect to MySQL server on 'localhost:3306' (111)

The above exception was the direct cause of the following exception:

Traceback (most recent call last):
  File "/app/app.py", line 192, in get_data
    connection = mysql.connector.connect(**db_config)
  File "/usr/local/lib/python3.9/site-packages/mysql/connector/pooling.py", line 322, in connect
    return CMySQLConnection(*args, **kwargs)
  File "/usr/local/lib/python3.9/site-packages/mysql/connector/connection_cext.py", line 151, in __init__
    self.connect(**kwargs)
  File "/usr/local/lib/python3.9/site-packages/mysql/connector/abstracts.py", line 1426, in connect
    self._open_connection()
  File "/usr/local/lib/python3.9/site-packages/mysql/connector/connection_cext.py", line 340, in _open_connection
    raise get_mysql_exception(
mysql.connector.errors.DatabaseError: 2003 (HY000): Can't connect to MySQL server on 'localhost:3306' (111)
2024-11-03 11:35:24,725 ERROR Error fetching data: 2003 (HY000): Can't connect to MySQL server on 'localhost:3306' (111)
Traceback (most recent call last):
  File "/usr/local/lib/python3.9/site-packages/mysql/connector/connection_cext.py", line 335, in _open_connection
    self._cmysql.connect(**cnx_kwargs)
_mysql_connector.MySQLInterfaceError: Can't connect to MySQL server on 'localhost:3306' (111)

The above exception was the direct cause of the following exception:

Traceback (most recent call last):
  File "/app/app.py", line 192, in get_data
    connection = mysql.connector.connect(**db_config)
  File "/usr/local/lib/python3.9/site-packages/mysql/connector/pooling.py", line 322, in connect
    return CMySQLConnection(*args, **kwargs)
  File "/usr/local/lib/python3.9/site-packages/mysql/connector/connection_cext.py", line 151, in __init__
    self.connect(**kwargs)
  File "/usr/local/lib/python3.9/site-packages/mysql/connector/abstracts.py", line 1426, in connect
    self._open_connection()
  File "/usr/local/lib/python3.9/site-packages/mysql/connector/connection_cext.py", line 340, in _open_connection
    raise get_mysql_exception(
mysql.connector.errors.DatabaseError: 2003 (HY000): Can't connect to MySQL server on 'localhost:3306' (111)
2024-11-03 11:35:24,878 ERROR Error fetching data: 2003 (HY000): Can't connect to MySQL server on 'localhost:3306' (111)
Traceback (most recent call last):
  File "/usr/local/lib/python3.9/site-packages/mysql/connector/connection_cext.py", line 335, in _open_connection
    self._cmysql.connect(**cnx_kwargs)
_mysql_connector.MySQLInterfaceError: Can't connect to MySQL server on 'localhost:3306' (111)

The above exception was the direct cause of the following exception:

Traceback (most recent call last):
  File "/app/app.py", line 192, in get_data
    connection = mysql.connector.connect(**db_config)
  File "/usr/local/lib/python3.9/site-packages/mysql/connector/pooling.py", line 322, in connect
    return CMySQLConnection(*args, **kwargs)
  File "/usr/local/lib/python3.9/site-packages/mysql/connector/connection_cext.py", line 151, in __init__
    self.connect(**kwargs)
  File "/usr/local/lib/python3.9/site-packages/mysql/connector/abstracts.py", line 1426, in connect
    self._open_connection()
  File "/usr/local/lib/python3.9/site-packages/mysql/connector/connection_cext.py", line 340, in _open_connection
    raise get_mysql_exception(
mysql.connector.errors.DatabaseError: 2003 (HY000): Can't connect to MySQL server on 'localhost:3306' (111)
2024-11-03 11:35:25,069 ERROR Error fetching data: 2003 (HY000): Can't connect to MySQL server on 'localhost:3306' (111)
Traceback (most recent call last):
  File "/usr/local/lib/python3.9/site-packages/mysql/connector/connection_cext.py", line 335, in _open_connection
    self._cmysql.connect(**cnx_kwargs)
_mysql_connector.MySQLInterfaceError: Can't connect to MySQL server on 'localhost:3306' (111)

The above exception was the direct cause of the following exception:

Traceback (most recent call last):
  File "/app/app.py", line 192, in get_data
    connection = mysql.connector.connect(**db_config)
  File "/usr/local/lib/python3.9/site-packages/mysql/connector/pooling.py", line 322, in connect
    return CMySQLConnection(*args, **kwargs)
  File "/usr/local/lib/python3.9/site-packages/mysql/connector/connection_cext.py", line 151, in __init__
    self.connect(**kwargs)
  File "/usr/local/lib/python3.9/site-packages/mysql/connector/abstracts.py", line 1426, in connect
    self._open_connection()
  File "/usr/local/lib/python3.9/site-packages/mysql/connector/connection_cext.py", line 340, in _open_connection
    raise get_mysql_exception(
mysql.connector.errors.DatabaseError: 2003 (HY000): Can't connect to MySQL server on 'localhost:3306' (111)
2024-11-03 11:35:25,228 ERROR Error fetching data: 2003 (HY000): Can't connect to MySQL server on 'localhost:3306' (111)
Traceback (most recent call last):
  File "/usr/local/lib/python3.9/site-packages/mysql/connector/connection_cext.py", line 335, in _open_connection
    self._cmysql.connect(**cnx_kwargs)
_mysql_connector.MySQLInterfaceError: Can't connect to MySQL server on 'localhost:3306' (111)

The above exception was the direct cause of the following exception:

Traceback (most recent call last):
  File "/app/app.py", line 192, in get_data
    connection = mysql.connector.connect(**db_config)
  File "/usr/local/lib/python3.9/site-packages/mysql/connector/pooling.py", line 322, in connect
    return CMySQLConnection(*args, **kwargs)
  File "/usr/local/lib/python3.9/site-packages/mysql/connector/connection_cext.py", line 151, in __init__
    self.connect(**kwargs)
  File "/usr/local/lib/python3.9/site-packages/mysql/connector/abstracts.py", line 1426, in connect
    self._open_connection()
  File "/usr/local/lib/python3.9/site-packages/mysql/connector/connection_cext.py", line 340, in _open_connection
    raise get_mysql_exception(
mysql.connector.errors.DatabaseError: 2003 (HY000): Can't connect to MySQL server on 'localhost:3306' (111)
2024-11-03 11:35:25,426 ERROR Error fetching data: 2003 (HY000): Can't connect to MySQL server on 'localhost:3306' (111)
Traceback (most recent call last):
  File "/usr/local/lib/python3.9/site-packages/mysql/connector/connection_cext.py", line 335, in _open_connection
    self._cmysql.connect(**cnx_kwargs)
_mysql_connector.MySQLInterfaceError: Can't connect to MySQL server on 'localhost:3306' (111)

The above exception was the direct cause of the following exception:

Traceback (most recent call last):
  File "/app/app.py", line 192, in get_data
    connection = mysql.connector.connect(**db_config)
  File "/usr/local/lib/python3.9/site-packages/mysql/connector/pooling.py", line 322, in connect
    return CMySQLConnection(*args, **kwargs)
  File "/usr/local/lib/python3.9/site-packages/mysql/connector/connection_cext.py", line 151, in __init__
    self.connect(**kwargs)
  File "/usr/local/lib/python3.9/site-packages/mysql/connector/abstracts.py", line 1426, in connect
    self._open_connection()
  File "/usr/local/lib/python3.9/site-packages/mysql/connector/connection_cext.py", line 340, in _open_connection
    raise get_mysql_exception(
mysql.connector.errors.DatabaseError: 2003 (HY000): Can't connect to MySQL server on 'localhost:3306' (111)
2024-11-03 11:35:25,589 ERROR Error fetching data: 2003 (HY000): Can't connect to MySQL server on 'localhost:3306' (111)
Traceback (most recent call last):
  File "/usr/local/lib/python3.9/site-packages/mysql/connector/connection_cext.py", line 335, in _open_connection
    self._cmysql.connect(**cnx_kwargs)
_mysql_connector.MySQLInterfaceError: Can't connect to MySQL server on 'localhost:3306' (111)

The above exception was the direct cause of the following exception:

Traceback (most recent call last):
  File "/app/app.py", line 192, in get_data
    connection = mysql.connector.connect(**db_config)
  File "/usr/local/lib/python3.9/site-packages/mysql/connector/pooling.py", line 322, in connect
    return CMySQLConnection(*args, **kwargs)
  File "/usr/local/lib/python3.9/site-packages/mysql/connector/connection_cext.py", line 151, in __init__
    self.connect(**kwargs)
  File "/usr/local/lib/python3.9/site-packages/mysql/connector/abstracts.py", line 1426, in connect
    self._open_connection()
  File "/usr/local/lib/python3.9/site-packages/mysql/connector/connection_cext.py", line 340, in _open_connection
    raise get_mysql_exception(
mysql.connector.errors.DatabaseError: 2003 (HY000): Can't connect to MySQL server on 'localhost:3306' (111)
2024-11-03 11:35:25,767 ERROR Error fetching data: 2003 (HY000): Can't connect to MySQL server on 'localhost:3306' (111)
Traceback (most recent call last):
  File "/usr/local/lib/python3.9/site-packages/mysql/connector/connection_cext.py", line 335, in _open_connection
    self._cmysql.connect(**cnx_kwargs)
_mysql_connector.MySQLInterfaceError: Can't connect to MySQL server on 'localhost:3306' (111)

The above exception was the direct cause of the following exception:

Traceback (most recent call last):
  File "/app/app.py", line 192, in get_data
    connection = mysql.connector.connect(**db_config)
  File "/usr/local/lib/python3.9/site-packages/mysql/connector/pooling.py", line 322, in connect
    return CMySQLConnection(*args, **kwargs)
  File "/usr/local/lib/python3.9/site-packages/mysql/connector/connection_cext.py", line 151, in __init__
    self.connect(**kwargs)
  File "/usr/local/lib/python3.9/site-packages/mysql/connector/abstracts.py", line 1426, in connect
    self._open_connection()
  File "/usr/local/lib/python3.9/site-packages/mysql/connector/connection_cext.py", line 340, in _open_connection
    raise get_mysql_exception(
mysql.connector.errors.DatabaseError: 2003 (HY000): Can't connect to MySQL server on 'localhost:3306' (111)
2024-11-03 11:35:25,932 ERROR Error fetching data: 2003 (HY000): Can't connect to MySQL server on 'localhost:3306' (111)
Traceback (most recent call last):
  File "/usr/local/lib/python3.9/site-packages/mysql/connector/connection_cext.py", line 335, in _open_connection
    self._cmysql.connect(**cnx_kwargs)
_mysql_connector.MySQLInterfaceError: Can't connect to MySQL server on 'localhost:3306' (111)

The above exception was the direct cause of the following exception:

Traceback (most recent call last):
  File "/app/app.py", line 192, in get_data
    connection = mysql.connector.connect(**db_config)
  File "/usr/local/lib/python3.9/site-packages/mysql/connector/pooling.py", line 322, in connect
    return CMySQLConnection(*args, **kwargs)
  File "/usr/local/lib/python3.9/site-packages/mysql/connector/connection_cext.py", line 151, in __init__
    self.connect(**kwargs)
  File "/usr/local/lib/python3.9/site-packages/mysql/connector/abstracts.py", line 1426, in connect
    self._open_connection()
  File "/usr/local/lib/python3.9/site-packages/mysql/connector/connection_cext.py", line 340, in _open_connection
    raise get_mysql_exception(
mysql.connector.errors.DatabaseError: 2003 (HY000): Can't connect to MySQL server on 'localhost:3306' (111)
2024-11-03 11:35:26,152 ERROR Error fetching data: 2003 (HY000): Can't connect to MySQL server on 'localhost:3306' (111)
Traceback (most recent call last):
  File "/usr/local/lib/python3.9/site-packages/mysql/connector/connection_cext.py", line 335, in _open_connection
    self._cmysql.connect(**cnx_kwargs)
_mysql_connector.MySQLInterfaceError: Can't connect to MySQL server on 'localhost:3306' (111)

The above exception was the direct cause of the following exception:

Traceback (most recent call last):
  File "/app/app.py", line 192, in get_data
    connection = mysql.connector.connect(**db_config)
  File "/usr/local/lib/python3.9/site-packages/mysql/connector/pooling.py", line 322, in connect
    return CMySQLConnection(*args, **kwargs)
  File "/usr/local/lib/python3.9/site-packages/mysql/connector/connection_cext.py", line 151, in __init__
    self.connect(**kwargs)
  File "/usr/local/lib/python3.9/site-packages/mysql/connector/abstracts.py", line 1426, in connect
    self._open_connection()
  File "/usr/local/lib/python3.9/site-packages/mysql/connector/connection_cext.py", line 340, in _open_connection
    raise get_mysql_exception(
mysql.connector.errors.DatabaseError: 2003 (HY000): Can't connect to MySQL server on 'localhost:3306' (111)
2024-11-03 11:35:27,921 ERROR Error fetching data: 2003 (HY000): Can't connect to MySQL server on 'localhost:3306' (111)
Traceback (most recent call last):
  File "/usr/local/lib/python3.9/site-packages/mysql/connector/connection_cext.py", line 335, in _open_connection
    self._cmysql.connect(**cnx_kwargs)
_mysql_connector.MySQLInterfaceError: Can't connect to MySQL server on 'localhost:3306' (111)

The above exception was the direct cause of the following exception:

Traceback (most recent call last):
  File "/app/app.py", line 192, in get_data
    connection = mysql.connector.connect(**db_config)
  File "/usr/local/lib/python3.9/site-packages/mysql/connector/pooling.py", line 322, in connect
    return CMySQLConnection(*args, **kwargs)
  File "/usr/local/lib/python3.9/site-packages/mysql/connector/connection_cext.py", line 151, in __init__
    self.connect(**kwargs)
  File "/usr/local/lib/python3.9/site-packages/mysql/connector/abstracts.py", line 1426, in connect
    self._open_connection()
  File "/usr/local/lib/python3.9/site-packages/mysql/connector/connection_cext.py", line 340, in _open_connection
    raise get_mysql_exception(
mysql.connector.errors.DatabaseError: 2003 (HY000): Can't connect to MySQL server on 'localhost:3306' (111)
2024-11-03 11:35:28,081 ERROR Error fetching data: 2003 (HY000): Can't connect to MySQL server on 'localhost:3306' (111)
Traceback (most recent call last):
  File "/usr/local/lib/python3.9/site-packages/mysql/connector/connection_cext.py", line 335, in _open_connection
    self._cmysql.connect(**cnx_kwargs)
_mysql_connector.MySQLInterfaceError: Can't connect to MySQL server on 'localhost:3306' (111)

The above exception was the direct cause of the following exception:

Traceback (most recent call last):
  File "/app/app.py", line 192, in get_data
    connection = mysql.connector.connect(**db_config)
  File "/usr/local/lib/python3.9/site-packages/mysql/connector/pooling.py", line 322, in connect
    return CMySQLConnection(*args, **kwargs)
  File "/usr/local/lib/python3.9/site-packages/mysql/connector/connection_cext.py", line 151, in __init__
    self.connect(**kwargs)
  File "/usr/local/lib/python3.9/site-packages/mysql/connector/abstracts.py", line 1426, in connect
    self._open_connection()
  File "/usr/local/lib/python3.9/site-packages/mysql/connector/connection_cext.py", line 340, in _open_connection
    raise get_mysql_exception(
mysql.connector.errors.DatabaseError: 2003 (HY000): Can't connect to MySQL server on 'localhost:3306' (111)
2024-11-03 11:35:28,310 ERROR Error fetching data: 2003 (HY000): Can't connect to MySQL server on 'localhost:3306' (111)
Traceback (most recent call last):
  File "/usr/local/lib/python3.9/site-packages/mysql/connector/connection_cext.py", line 335, in _open_connection
    self._cmysql.connect(**cnx_kwargs)
_mysql_connector.MySQLInterfaceError: Can't connect to MySQL server on 'localhost:3306' (111)

The above exception was the direct cause of the following exception:

Traceback (most recent call last):
  File "/app/app.py", line 192, in get_data
    connection = mysql.connector.connect(**db_config)
  File "/usr/local/lib/python3.9/site-packages/mysql/connector/pooling.py", line 322, in connect
    return CMySQLConnection(*args, **kwargs)
  File "/usr/local/lib/python3.9/site-packages/mysql/connector/connection_cext.py", line 151, in __init__
    self.connect(**kwargs)
  File "/usr/local/lib/python3.9/site-packages/mysql/connector/abstracts.py", line 1426, in connect
    self._open_connection()
  File "/usr/local/lib/python3.9/site-packages/mysql/connector/connection_cext.py", line 340, in _open_connection
    raise get_mysql_exception(
mysql.connector.errors.DatabaseError: 2003 (HY000): Can't connect to MySQL server on 'localhost:3306' (111)
2024-11-03 11:35:49,283 ERROR Error fetching data: 2003 (HY000): Can't connect to MySQL server on 'localhost:3306' (111)
Traceback (most recent call last):
  File "/usr/local/lib/python3.9/site-packages/mysql/connector/connection_cext.py", line 335, in _open_connection
    self._cmysql.connect(**cnx_kwargs)
_mysql_connector.MySQLInterfaceError: Can't connect to MySQL server on 'localhost:3306' (111)

The above exception was the direct cause of the following exception:

Traceback (most recent call last):
  File "/app/app.py", line 192, in get_data
    connection = mysql.connector.connect(**db_config)
  File "/usr/local/lib/python3.9/site-packages/mysql/connector/pooling.py", line 322, in connect
    return CMySQLConnection(*args, **kwargs)
  File "/usr/local/lib/python3.9/site-packages/mysql/connector/connection_cext.py", line 151, in __init__
    self.connect(**kwargs)
  File "/usr/local/lib/python3.9/site-packages/mysql/connector/abstracts.py", line 1426, in connect
    self._open_connection()
  File "/usr/local/lib/python3.9/site-packages/mysql/connector/connection_cext.py", line 340, in _open_connection
    raise get_mysql_exception(
mysql.connector.errors.DatabaseError: 2003 (HY000): Can't connect to MySQL server on 'localhost:3306' (111)
2024-11-03 11:35:49,724 ERROR Error fetching data: 2003 (HY000): Can't connect to MySQL server on 'localhost:3306' (111)
Traceback (most recent call last):
  File "/usr/local/lib/python3.9/site-packages/mysql/connector/connection_cext.py", line 335, in _open_connection
    self._cmysql.connect(**cnx_kwargs)
_mysql_connector.MySQLInterfaceError: Can't connect to MySQL server on 'localhost:3306' (111)

The above exception was the direct cause of the following exception:

Traceback (most recent call last):
  File "/app/app.py", line 192, in get_data
    connection = mysql.connector.connect(**db_config)
  File "/usr/local/lib/python3.9/site-packages/mysql/connector/pooling.py", line 322, in connect
    return CMySQLConnection(*args, **kwargs)
  File "/usr/local/lib/python3.9/site-packages/mysql/connector/connection_cext.py", line 151, in __init__
    self.connect(**kwargs)
  File "/usr/local/lib/python3.9/site-packages/mysql/connector/abstracts.py", line 1426, in connect
    self._open_connection()
  File "/usr/local/lib/python3.9/site-packages/mysql/connector/connection_cext.py", line 340, in _open_connection
    raise get_mysql_exception(
mysql.connector.errors.DatabaseError: 2003 (HY000): Can't connect to MySQL server on 'localhost:3306' (111)
2024-11-03 11:35:49,906 ERROR Error fetching data: 2003 (HY000): Can't connect to MySQL server on 'localhost:3306' (111)
Traceback (most recent call last):
  File "/usr/local/lib/python3.9/site-packages/mysql/connector/connection_cext.py", line 335, in _open_connection
    self._cmysql.connect(**cnx_kwargs)
_mysql_connector.MySQLInterfaceError: Can't connect to MySQL server on 'localhost:3306' (111)

The above exception was the direct cause of the following exception:

Traceback (most recent call last):
  File "/app/app.py", line 192, in get_data
    connection = mysql.connector.connect(**db_config)
  File "/usr/local/lib/python3.9/site-packages/mysql/connector/pooling.py", line 322, in connect
    return CMySQLConnection(*args, **kwargs)
  File "/usr/local/lib/python3.9/site-packages/mysql/connector/connection_cext.py", line 151, in __init__
    self.connect(**kwargs)
  File "/usr/local/lib/python3.9/site-packages/mysql/connector/abstracts.py", line 1426, in connect
    self._open_connection()
  File "/usr/local/lib/python3.9/site-packages/mysql/connector/connection_cext.py", line 340, in _open_connection
    raise get_mysql_exception(
mysql.connector.errors.DatabaseError: 2003 (HY000): Can't connect to MySQL server on 'localhost:3306' (111)
2024-11-03 11:35:50,080 ERROR Error fetching data: 2003 (HY000): Can't connect to MySQL server on 'localhost:3306' (111)
Traceback (most recent call last):
  File "/usr/local/lib/python3.9/site-packages/mysql/connector/connection_cext.py", line 335, in _open_connection
    self._cmysql.connect(**cnx_kwargs)
_mysql_connector.MySQLInterfaceError: Can't connect to MySQL server on 'localhost:3306' (111)

The above exception was the direct cause of the following exception:

Traceback (most recent call last):
  File "/app/app.py", line 192, in get_data
    connection = mysql.connector.connect(**db_config)
  File "/usr/local/lib/python3.9/site-packages/mysql/connector/pooling.py", line 322, in connect
    return CMySQLConnection(*args, **kwargs)
  File "/usr/local/lib/python3.9/site-packages/mysql/connector/connection_cext.py", line 151, in __init__
    self.connect(**kwargs)
  File "/usr/local/lib/python3.9/site-packages/mysql/connector/abstracts.py", line 1426, in connect
    self._open_connection()
  File "/usr/local/lib/python3.9/site-packages/mysql/connector/connection_cext.py", line 340, in _open_connection
    raise get_mysql_exception(
mysql.connector.errors.DatabaseError: 2003 (HY000): Can't connect to MySQL server on 'localhost:3306' (111)
2024-11-03 11:35:50,251 ERROR Error fetching data: 2003 (HY000): Can't connect to MySQL server on 'localhost:3306' (111)
Traceback (most recent call last):
  File "/usr/local/lib/python3.9/site-packages/mysql/connector/connection_cext.py", line 335, in _open_connection
    self._cmysql.connect(**cnx_kwargs)
_mysql_connector.MySQLInterfaceError: Can't connect to MySQL server on 'localhost:3306' (111)

The above exception was the direct cause of the following exception:

Traceback (most recent call last):
  File "/app/app.py", line 192, in get_data
    connection = mysql.connector.connect(**db_config)
  File "/usr/local/lib/python3.9/site-packages/mysql/connector/pooling.py", line 322, in connect
    return CMySQLConnection(*args, **kwargs)
  File "/usr/local/lib/python3.9/site-packages/mysql/connector/connection_cext.py", line 151, in __init__
    self.connect(**kwargs)
  File "/usr/local/lib/python3.9/site-packages/mysql/connector/abstracts.py", line 1426, in connect
    self._open_connection()
  File "/usr/local/lib/python3.9/site-packages/mysql/connector/connection_cext.py", line 340, in _open_connection
    raise get_mysql_exception(
mysql.connector.errors.DatabaseError: 2003 (HY000): Can't connect to MySQL server on 'localhost:3306' (111)
2024-11-09 12:15:01,902 ERROR Exception on /upload [POST]
Traceback (most recent call last):
  File "/usr/local/lib/python3.8/site-packages/flask/app.py", line 1473, in wsgi_app
    response = self.full_dispatch_request()
  File "/usr/local/lib/python3.8/site-packages/flask/app.py", line 882, in full_dispatch_request
    rv = self.handle_user_exception(e)
  File "/usr/local/lib/python3.8/site-packages/flask_cors/extension.py", line 194, in wrapped_function
    return cors_after_request(app.make_response(f(*args, **kwargs)))
  File "/usr/local/lib/python3.8/site-packages/flask/app.py", line 880, in full_dispatch_request
    rv = self.dispatch_request()
  File "/usr/local/lib/python3.8/site-packages/flask/app.py", line 865, in dispatch_request
    return self.ensure_sync(self.view_functions[rule.endpoint])(**view_args)  # type: ignore[no-any-return]
  File "/app/routes.py", line 149, in upload_data
    cursor.close()
UnboundLocalError: local variable 'cursor' referenced before assignment
2024-11-09 12:49:07,482 ERROR Exception on /upload [POST]
Traceback (most recent call last):
  File "/usr/local/lib/python3.8/site-packages/flask/app.py", line 1473, in wsgi_app
    response = self.full_dispatch_request()
  File "/usr/local/lib/python3.8/site-packages/flask/app.py", line 882, in full_dispatch_request
    rv = self.handle_user_exception(e)
  File "/usr/local/lib/python3.8/site-packages/flask_cors/extension.py", line 194, in wrapped_function
    return cors_after_request(app.make_response(f(*args, **kwargs)))
  File "/usr/local/lib/python3.8/site-packages/flask/app.py", line 880, in full_dispatch_request
    rv = self.dispatch_request()
  File "/usr/local/lib/python3.8/site-packages/flask/app.py", line 865, in dispatch_request
    return self.ensure_sync(self.view_functions[rule.endpoint])(**view_args)  # type: ignore[no-any-return]
  File "/app/routes.py", line 149, in upload_data
    cursor.close()
UnboundLocalError: local variable 'cursor' referenced before assignment
2024-11-09 12:49:09,223 ERROR Exception on /upload [POST]
Traceback (most recent call last):
  File "/usr/local/lib/python3.8/site-packages/flask/app.py", line 1473, in wsgi_app
    response = self.full_dispatch_request()
  File "/usr/local/lib/python3.8/site-packages/flask/app.py", line 882, in full_dispatch_request
    rv = self.handle_user_exception(e)
  File "/usr/local/lib/python3.8/site-packages/flask_cors/extension.py", line 194, in wrapped_function
    return cors_after_request(app.make_response(f(*args, **kwargs)))
  File "/usr/local/lib/python3.8/site-packages/flask/app.py", line 880, in full_dispatch_request
    rv = self.dispatch_request()
  File "/usr/local/lib/python3.8/site-packages/flask/app.py", line 865, in dispatch_request
    return self.ensure_sync(self.view_functions[rule.endpoint])(**view_args)  # type: ignore[no-any-return]
  File "/app/routes.py", line 149, in upload_data
    cursor.close()
UnboundLocalError: local variable 'cursor' referenced before assignment
2024-11-09 13:49:21,934 ERROR Exception on /getdata [GET]
Traceback (most recent call last):
  File "/usr/local/lib/python3.8/site-packages/flask/app.py", line 1473, in wsgi_app
    response = self.full_dispatch_request()
  File "/usr/local/lib/python3.8/site-packages/flask/app.py", line 882, in full_dispatch_request
    rv = self.handle_user_exception(e)
  File "/usr/local/lib/python3.8/site-packages/flask_cors/extension.py", line 194, in wrapped_function
    return cors_after_request(app.make_response(f(*args, **kwargs)))
  File "/usr/local/lib/python3.8/site-packages/flask/app.py", line 880, in full_dispatch_request
    rv = self.dispatch_request()
  File "/usr/local/lib/python3.8/site-packages/flask/app.py", line 865, in dispatch_request
    return self.ensure_sync(self.view_functions[rule.endpoint])(**view_args)  # type: ignore[no-any-return]
  File "/app/routes.py", line 90, in get_data
    cursor.close()
UnboundLocalError: local variable 'cursor' referenced before assignment
2024-11-09 14:21:01,243 ERROR Exception on /favorite [GET]
Traceback (most recent call last):
  File "/usr/local/lib/python3.8/site-packages/flask/app.py", line 1473, in wsgi_app
    response = self.full_dispatch_request()
  File "/usr/local/lib/python3.8/site-packages/flask/app.py", line 882, in full_dispatch_request
    rv = self.handle_user_exception(e)
  File "/usr/local/lib/python3.8/site-packages/flask_cors/extension.py", line 194, in wrapped_function
    return cors_after_request(app.make_response(f(*args, **kwargs)))
  File "/usr/local/lib/python3.8/site-packages/flask/app.py", line 880, in full_dispatch_request
    rv = self.dispatch_request()
  File "/usr/local/lib/python3.8/site-packages/flask/app.py", line 865, in dispatch_request
    return self.ensure_sync(self.view_functions[rule.endpoint])(**view_args)  # type: ignore[no-any-return]
  File "/app/routes.py", line 300, in get_favorites
    cursor.close()
UnboundLocalError: local variable 'cursor' referenced before assignment
2024-11-09 14:21:01,368 ERROR Exception on /favorite [GET]
Traceback (most recent call last):
  File "/usr/local/lib/python3.8/site-packages/flask/app.py", line 1473, in wsgi_app
    response = self.full_dispatch_request()
  File "/usr/local/lib/python3.8/site-packages/flask/app.py", line 882, in full_dispatch_request
    rv = self.handle_user_exception(e)
  File "/usr/local/lib/python3.8/site-packages/flask_cors/extension.py", line 194, in wrapped_function
    return cors_after_request(app.make_response(f(*args, **kwargs)))
  File "/usr/local/lib/python3.8/site-packages/flask/app.py", line 880, in full_dispatch_request
    rv = self.dispatch_request()
  File "/usr/local/lib/python3.8/site-packages/flask/app.py", line 865, in dispatch_request
    return self.ensure_sync(self.view_functions[rule.endpoint])(**view_args)  # type: ignore[no-any-return]
  File "/app/routes.py", line 300, in get_favorites
    cursor.close()
UnboundLocalError: local variable 'cursor' referenced before assignment
2024-11-09 14:59:01,471 ERROR Exception on /favorite [GET]
Traceback (most recent call last):
  File "/usr/local/lib/python3.8/site-packages/flask/app.py", line 1473, in wsgi_app
    response = self.full_dispatch_request()
  File "/usr/local/lib/python3.8/site-packages/flask/app.py", line 882, in full_dispatch_request
    rv = self.handle_user_exception(e)
  File "/usr/local/lib/python3.8/site-packages/flask_cors/extension.py", line 194, in wrapped_function
    return cors_after_request(app.make_response(f(*args, **kwargs)))
  File "/usr/local/lib/python3.8/site-packages/flask/app.py", line 880, in full_dispatch_request
    rv = self.dispatch_request()
  File "/usr/local/lib/python3.8/site-packages/flask/app.py", line 865, in dispatch_request
    return self.ensure_sync(self.view_functions[rule.endpoint])(**view_args)  # type: ignore[no-any-return]
  File "/app/routes.py", line 300, in get_favorites
    cursor.close()
UnboundLocalError: local variable 'cursor' referenced before assignment
2024-11-09 14:59:01,948 ERROR Exception on /favorite [GET]
Traceback (most recent call last):
  File "/usr/local/lib/python3.8/site-packages/flask/app.py", line 1473, in wsgi_app
    response = self.full_dispatch_request()
  File "/usr/local/lib/python3.8/site-packages/flask/app.py", line 882, in full_dispatch_request
    rv = self.handle_user_exception(e)
  File "/usr/local/lib/python3.8/site-packages/flask_cors/extension.py", line 194, in wrapped_function
    return cors_after_request(app.make_response(f(*args, **kwargs)))
  File "/usr/local/lib/python3.8/site-packages/flask/app.py", line 880, in full_dispatch_request
    rv = self.dispatch_request()
  File "/usr/local/lib/python3.8/site-packages/flask/app.py", line 865, in dispatch_request
    return self.ensure_sync(self.view_functions[rule.endpoint])(**view_args)  # type: ignore[no-any-return]
  File "/app/routes.py", line 300, in get_favorites
    cursor.close()
UnboundLocalError: local variable 'cursor' referenced before assignment
2024-11-09 15:05:59,094 ERROR Exception on /favorite [GET]
Traceback (most recent call last):
  File "/usr/local/lib/python3.8/site-packages/flask/app.py", line 1473, in wsgi_app
    response = self.full_dispatch_request()
  File "/usr/local/lib/python3.8/site-packages/flask/app.py", line 882, in full_dispatch_request
    rv = self.handle_user_exception(e)
  File "/usr/local/lib/python3.8/site-packages/flask_cors/extension.py", line 194, in wrapped_function
    return cors_after_request(app.make_response(f(*args, **kwargs)))
  File "/usr/local/lib/python3.8/site-packages/flask/app.py", line 880, in full_dispatch_request
    rv = self.dispatch_request()
  File "/usr/local/lib/python3.8/site-packages/flask/app.py", line 865, in dispatch_request
    return self.ensure_sync(self.view_functions[rule.endpoint])(**view_args)  # type: ignore[no-any-return]
  File "/app/routes.py", line 300, in get_favorites
    cursor.close()
UnboundLocalError: local variable 'cursor' referenced before assignment
2024-11-09 15:39:46,493 ERROR Exception on /favorite [GET]
Traceback (most recent call last):
  File "/usr/local/lib/python3.8/site-packages/flask/app.py", line 1473, in wsgi_app
    response = self.full_dispatch_request()
  File "/usr/local/lib/python3.8/site-packages/flask/app.py", line 882, in full_dispatch_request
    rv = self.handle_user_exception(e)
  File "/usr/local/lib/python3.8/site-packages/flask_cors/extension.py", line 194, in wrapped_function
    return cors_after_request(app.make_response(f(*args, **kwargs)))
  File "/usr/local/lib/python3.8/site-packages/flask/app.py", line 880, in full_dispatch_request
    rv = self.dispatch_request()
  File "/usr/local/lib/python3.8/site-packages/flask/app.py", line 865, in dispatch_request
    return self.ensure_sync(self.view_functions[rule.endpoint])(**view_args)  # type: ignore[no-any-return]
  File "/app/routes.py", line 300, in get_favorites
    cursor.close()
UnboundLocalError: local variable 'cursor' referenced before assignment
2024-11-09 15:42:03,080 ERROR Exception on /favorite [GET]
Traceback (most recent call last):
  File "/usr/local/lib/python3.8/site-packages/flask/app.py", line 1473, in wsgi_app
    response = self.full_dispatch_request()
  File "/usr/local/lib/python3.8/site-packages/flask/app.py", line 882, in full_dispatch_request
    rv = self.handle_user_exception(e)
  File "/usr/local/lib/python3.8/site-packages/flask_cors/extension.py", line 194, in wrapped_function
    return cors_after_request(app.make_response(f(*args, **kwargs)))
  File "/usr/local/lib/python3.8/site-packages/flask/app.py", line 880, in full_dispatch_request
    rv = self.dispatch_request()
  File "/usr/local/lib/python3.8/site-packages/flask/app.py", line 865, in dispatch_request
    return self.ensure_sync(self.view_functions[rule.endpoint])(**view_args)  # type: ignore[no-any-return]
  File "/app/routes.py", line 300, in get_favorites
    cursor.close()
UnboundLocalError: local variable 'cursor' referenced before assignment
2024-11-09 15:47:45,681 ERROR Exception on /favorite [GET]
Traceback (most recent call last):
  File "/usr/local/lib/python3.8/site-packages/flask/app.py", line 1473, in wsgi_app
    response = self.full_dispatch_request()
  File "/usr/local/lib/python3.8/site-packages/flask/app.py", line 882, in full_dispatch_request
    rv = self.handle_user_exception(e)
  File "/usr/local/lib/python3.8/site-packages/flask_cors/extension.py", line 194, in wrapped_function
    return cors_after_request(app.make_response(f(*args, **kwargs)))
  File "/usr/local/lib/python3.8/site-packages/flask/app.py", line 880, in full_dispatch_request
    rv = self.dispatch_request()
  File "/usr/local/lib/python3.8/site-packages/flask/app.py", line 865, in dispatch_request
    return self.ensure_sync(self.view_functions[rule.endpoint])(**view_args)  # type: ignore[no-any-return]
  File "/app/routes.py", line 300, in get_favorites
    cursor.close()
UnboundLocalError: local variable 'cursor' referenced before assignment
2024-11-09 15:47:46,459 ERROR Exception on /favorite [GET]
Traceback (most recent call last):
  File "/usr/local/lib/python3.8/site-packages/flask/app.py", line 1473, in wsgi_app
    response = self.full_dispatch_request()
  File "/usr/local/lib/python3.8/site-packages/flask/app.py", line 882, in full_dispatch_request
    rv = self.handle_user_exception(e)
  File "/usr/local/lib/python3.8/site-packages/flask_cors/extension.py", line 194, in wrapped_function
    return cors_after_request(app.make_response(f(*args, **kwargs)))
  File "/usr/local/lib/python3.8/site-packages/flask/app.py", line 880, in full_dispatch_request
    rv = self.dispatch_request()
  File "/usr/local/lib/python3.8/site-packages/flask/app.py", line 865, in dispatch_request
    return self.ensure_sync(self.view_functions[rule.endpoint])(**view_args)  # type: ignore[no-any-return]
  File "/app/routes.py", line 300, in get_favorites
    cursor.close()
UnboundLocalError: local variable 'cursor' referenced before assignment
2024-11-09 15:53:58,597 ERROR Exception on /favorite [GET]
Traceback (most recent call last):
  File "/usr/local/lib/python3.8/site-packages/flask/app.py", line 1473, in wsgi_app
    response = self.full_dispatch_request()
  File "/usr/local/lib/python3.8/site-packages/flask/app.py", line 882, in full_dispatch_request
    rv = self.handle_user_exception(e)
  File "/usr/local/lib/python3.8/site-packages/flask_cors/extension.py", line 194, in wrapped_function
    return cors_after_request(app.make_response(f(*args, **kwargs)))
  File "/usr/local/lib/python3.8/site-packages/flask/app.py", line 880, in full_dispatch_request
    rv = self.dispatch_request()
  File "/usr/local/lib/python3.8/site-packages/flask/app.py", line 865, in dispatch_request
    return self.ensure_sync(self.view_functions[rule.endpoint])(**view_args)  # type: ignore[no-any-return]
  File "/app/routes.py", line 300, in get_favorites
    cursor.close()
UnboundLocalError: local variable 'cursor' referenced before assignment
2024-11-09 17:56:30,040 ERROR Exception on /favorite [GET]
Traceback (most recent call last):
  File "/usr/local/lib/python3.8/site-packages/flask/app.py", line 1473, in wsgi_app
    response = self.full_dispatch_request()
  File "/usr/local/lib/python3.8/site-packages/flask/app.py", line 882, in full_dispatch_request
    rv = self.handle_user_exception(e)
  File "/usr/local/lib/python3.8/site-packages/flask_cors/extension.py", line 194, in wrapped_function
    return cors_after_request(app.make_response(f(*args, **kwargs)))
  File "/usr/local/lib/python3.8/site-packages/flask/app.py", line 880, in full_dispatch_request
    rv = self.dispatch_request()
  File "/usr/local/lib/python3.8/site-packages/flask/app.py", line 865, in dispatch_request
    return self.ensure_sync(self.view_functions[rule.endpoint])(**view_args)  # type: ignore[no-any-return]
  File "/app/routes.py", line 301, in get_favorites
    cursor.close()
UnboundLocalError: local variable 'cursor' referenced before assignment
2024-11-09 18:39:49,398 ERROR Exception on /favorite [GET]
Traceback (most recent call last):
  File "/usr/local/lib/python3.8/site-packages/flask/app.py", line 1473, in wsgi_app
    response = self.full_dispatch_request()
  File "/usr/local/lib/python3.8/site-packages/flask/app.py", line 882, in full_dispatch_request
    rv = self.handle_user_exception(e)
  File "/usr/local/lib/python3.8/site-packages/flask_cors/extension.py", line 194, in wrapped_function
    return cors_after_request(app.make_response(f(*args, **kwargs)))
  File "/usr/local/lib/python3.8/site-packages/flask/app.py", line 880, in full_dispatch_request
    rv = self.dispatch_request()
  File "/usr/local/lib/python3.8/site-packages/flask/app.py", line 865, in dispatch_request
    return self.ensure_sync(self.view_functions[rule.endpoint])(**view_args)  # type: ignore[no-any-return]
  File "/app/routes.py", line 301, in get_favorites
    cursor.close()
UnboundLocalError: local variable 'cursor' referenced before assignment
2024-11-09 19:14:15,285 ERROR Exception on /getdata [GET]
Traceback (most recent call last):
  File "/usr/local/lib/python3.8/site-packages/flask/app.py", line 1473, in wsgi_app
    response = self.full_dispatch_request()
  File "/usr/local/lib/python3.8/site-packages/flask/app.py", line 882, in full_dispatch_request
    rv = self.handle_user_exception(e)
  File "/usr/local/lib/python3.8/site-packages/flask_cors/extension.py", line 194, in wrapped_function
    return cors_after_request(app.make_response(f(*args, **kwargs)))
  File "/usr/local/lib/python3.8/site-packages/flask/app.py", line 880, in full_dispatch_request
    rv = self.dispatch_request()
  File "/usr/local/lib/python3.8/site-packages/flask/app.py", line 865, in dispatch_request
    return self.ensure_sync(self.view_functions[rule.endpoint])(**view_args)  # type: ignore[no-any-return]
  File "/app/routes.py", line 90, in get_data
    cursor.close()
UnboundLocalError: local variable 'cursor' referenced before assignment
2024-11-09 19:25:51,677 ERROR Exception on /getdata [GET]
Traceback (most recent call last):
  File "/usr/local/lib/python3.8/site-packages/flask/app.py", line 1473, in wsgi_app
    response = self.full_dispatch_request()
  File "/usr/local/lib/python3.8/site-packages/flask/app.py", line 882, in full_dispatch_request
    rv = self.handle_user_exception(e)
  File "/usr/local/lib/python3.8/site-packages/flask_cors/extension.py", line 194, in wrapped_function
    return cors_after_request(app.make_response(f(*args, **kwargs)))
  File "/usr/local/lib/python3.8/site-packages/flask/app.py", line 880, in full_dispatch_request
    rv = self.dispatch_request()
  File "/usr/local/lib/python3.8/site-packages/flask/app.py", line 865, in dispatch_request
    return self.ensure_sync(self.view_functions[rule.endpoint])(**view_args)  # type: ignore[no-any-return]
  File "/app/books_routes.py", line 20, in get_data
    cursor.close()
UnboundLocalError: local variable 'cursor' referenced before assignment
2024-11-13 13:15:42,811 ERROR Exception on /favorite [GET]
Traceback (most recent call last):
  File "/usr/local/lib/python3.8/site-packages/flask/app.py", line 1473, in wsgi_app
    response = self.full_dispatch_request()
  File "/usr/local/lib/python3.8/site-packages/flask/app.py", line 882, in full_dispatch_request
    rv = self.handle_user_exception(e)
  File "/usr/local/lib/python3.8/site-packages/flask_cors/extension.py", line 194, in wrapped_function
    return cors_after_request(app.make_response(f(*args, **kwargs)))
  File "/usr/local/lib/python3.8/site-packages/flask/app.py", line 880, in full_dispatch_request
    rv = self.dispatch_request()
  File "/usr/local/lib/python3.8/site-packages/flask/app.py", line 865, in dispatch_request
    return self.ensure_sync(self.view_functions[rule.endpoint])(**view_args)  # type: ignore[no-any-return]
  File "/app/favorite_routes.py", line 85, in get_favorites
    cursor.close()
UnboundLocalError: local variable 'cursor' referenced before assignment
2024-11-13 13:16:18,851 ERROR Exception on /favorite [GET]
Traceback (most recent call last):
  File "/usr/local/lib/python3.8/site-packages/flask/app.py", line 1473, in wsgi_app
    response = self.full_dispatch_request()
  File "/usr/local/lib/python3.8/site-packages/flask/app.py", line 882, in full_dispatch_request
    rv = self.handle_user_exception(e)
  File "/usr/local/lib/python3.8/site-packages/flask_cors/extension.py", line 194, in wrapped_function
    return cors_after_request(app.make_response(f(*args, **kwargs)))
  File "/usr/local/lib/python3.8/site-packages/flask/app.py", line 880, in full_dispatch_request
    rv = self.dispatch_request()
  File "/usr/local/lib/python3.8/site-packages/flask/app.py", line 865, in dispatch_request
    return self.ensure_sync(self.view_functions[rule.endpoint])(**view_args)  # type: ignore[no-any-return]
  File "/app/favorite_routes.py", line 85, in get_favorites
    cursor.close()
UnboundLocalError: local variable 'cursor' referenced before assignment
2024-11-13 13:18:19,244 ERROR Exception on /getdata [GET]
Traceback (most recent call last):
  File "/usr/local/lib/python3.8/site-packages/flask/app.py", line 1473, in wsgi_app
    response = self.full_dispatch_request()
  File "/usr/local/lib/python3.8/site-packages/flask/app.py", line 882, in full_dispatch_request
    rv = self.handle_user_exception(e)
  File "/usr/local/lib/python3.8/site-packages/flask_cors/extension.py", line 194, in wrapped_function
    return cors_after_request(app.make_response(f(*args, **kwargs)))
  File "/usr/local/lib/python3.8/site-packages/flask/app.py", line 880, in full_dispatch_request
    rv = self.dispatch_request()
  File "/usr/local/lib/python3.8/site-packages/flask/app.py", line 865, in dispatch_request
    return self.ensure_sync(self.view_functions[rule.endpoint])(**view_args)  # type: ignore[no-any-return]
  File "/app/books_routes.py", line 20, in get_data
    cursor.close()
UnboundLocalError: local variable 'cursor' referenced before assignment
2024-11-13 13:24:46,982 ERROR Exception on /favorite [GET]
Traceback (most recent call last):
  File "/usr/local/lib/python3.8/site-packages/flask/app.py", line 1473, in wsgi_app
    response = self.full_dispatch_request()
  File "/usr/local/lib/python3.8/site-packages/flask/app.py", line 882, in full_dispatch_request
    rv = self.handle_user_exception(e)
  File "/usr/local/lib/python3.8/site-packages/flask_cors/extension.py", line 194, in wrapped_function
    return cors_after_request(app.make_response(f(*args, **kwargs)))
  File "/usr/local/lib/python3.8/site-packages/flask/app.py", line 880, in full_dispatch_request
    rv = self.dispatch_request()
  File "/usr/local/lib/python3.8/site-packages/flask/app.py", line 865, in dispatch_request
    return self.ensure_sync(self.view_functions[rule.endpoint])(**view_args)  # type: ignore[no-any-return]
  File "/app/favorite_routes.py", line 85, in get_favorites
    cursor.close()
UnboundLocalError: local variable 'cursor' referenced before assignment
2024-11-13 13:27:22,897 ERROR Exception on /favorite [GET]
Traceback (most recent call last):
  File "/usr/local/lib/python3.8/site-packages/flask/app.py", line 1473, in wsgi_app
    response = self.full_dispatch_request()
  File "/usr/local/lib/python3.8/site-packages/flask/app.py", line 882, in full_dispatch_request
    rv = self.handle_user_exception(e)
  File "/usr/local/lib/python3.8/site-packages/flask_cors/extension.py", line 194, in wrapped_function
    return cors_after_request(app.make_response(f(*args, **kwargs)))
  File "/usr/local/lib/python3.8/site-packages/flask/app.py", line 880, in full_dispatch_request
    rv = self.dispatch_request()
  File "/usr/local/lib/python3.8/site-packages/flask/app.py", line 865, in dispatch_request
    return self.ensure_sync(self.view_functions[rule.endpoint])(**view_args)  # type: ignore[no-any-return]
  File "/app/favorite_routes.py", line 85, in get_favorites
    cursor.close()
UnboundLocalError: local variable 'cursor' referenced before assignment
2024-11-13 13:34:34,346 ERROR Exception on /favorite [GET]
Traceback (most recent call last):
  File "/usr/local/lib/python3.8/site-packages/flask/app.py", line 1473, in wsgi_app
    response = self.full_dispatch_request()
  File "/usr/local/lib/python3.8/site-packages/flask/app.py", line 882, in full_dispatch_request
    rv = self.handle_user_exception(e)
  File "/usr/local/lib/python3.8/site-packages/flask_cors/extension.py", line 194, in wrapped_function
    return cors_after_request(app.make_response(f(*args, **kwargs)))
  File "/usr/local/lib/python3.8/site-packages/flask/app.py", line 880, in full_dispatch_request
    rv = self.dispatch_request()
  File "/usr/local/lib/python3.8/site-packages/flask/app.py", line 865, in dispatch_request
    return self.ensure_sync(self.view_functions[rule.endpoint])(**view_args)  # type: ignore[no-any-return]
  File "/app/favorite_routes.py", line 85, in get_favorites
    cursor.close()
UnboundLocalError: local variable 'cursor' referenced before assignment
2024-11-13 13:34:35,423 ERROR Exception on /favorite [GET]
Traceback (most recent call last):
  File "/usr/local/lib/python3.8/site-packages/flask/app.py", line 1473, in wsgi_app
    response = self.full_dispatch_request()
  File "/usr/local/lib/python3.8/site-packages/flask/app.py", line 882, in full_dispatch_request
    rv = self.handle_user_exception(e)
  File "/usr/local/lib/python3.8/site-packages/flask_cors/extension.py", line 194, in wrapped_function
    return cors_after_request(app.make_response(f(*args, **kwargs)))
  File "/usr/local/lib/python3.8/site-packages/flask/app.py", line 880, in full_dispatch_request
    rv = self.dispatch_request()
  File "/usr/local/lib/python3.8/site-packages/flask/app.py", line 865, in dispatch_request
    return self.ensure_sync(self.view_functions[rule.endpoint])(**view_args)  # type: ignore[no-any-return]
  File "/app/favorite_routes.py", line 85, in get_favorites
    cursor.close()
UnboundLocalError: local variable 'cursor' referenced before assignment
2024-11-13 13:34:35,954 ERROR Exception on /favorite [GET]
Traceback (most recent call last):
  File "/usr/local/lib/python3.8/site-packages/flask/app.py", line 1473, in wsgi_app
    response = self.full_dispatch_request()
  File "/usr/local/lib/python3.8/site-packages/flask/app.py", line 882, in full_dispatch_request
    rv = self.handle_user_exception(e)
  File "/usr/local/lib/python3.8/site-packages/flask_cors/extension.py", line 194, in wrapped_function
    return cors_after_request(app.make_response(f(*args, **kwargs)))
  File "/usr/local/lib/python3.8/site-packages/flask/app.py", line 880, in full_dispatch_request
    rv = self.dispatch_request()
  File "/usr/local/lib/python3.8/site-packages/flask/app.py", line 865, in dispatch_request
    return self.ensure_sync(self.view_functions[rule.endpoint])(**view_args)  # type: ignore[no-any-return]
  File "/app/favorite_routes.py", line 85, in get_favorites
    cursor.close()
UnboundLocalError: local variable 'cursor' referenced before assignment
2024-11-13 13:34:36,401 ERROR Exception on /favorite [GET]
Traceback (most recent call last):
  File "/usr/local/lib/python3.8/site-packages/flask/app.py", line 1473, in wsgi_app
    response = self.full_dispatch_request()
  File "/usr/local/lib/python3.8/site-packages/flask/app.py", line 882, in full_dispatch_request
    rv = self.handle_user_exception(e)
  File "/usr/local/lib/python3.8/site-packages/flask_cors/extension.py", line 194, in wrapped_function
    return cors_after_request(app.make_response(f(*args, **kwargs)))
  File "/usr/local/lib/python3.8/site-packages/flask/app.py", line 880, in full_dispatch_request
    rv = self.dispatch_request()
  File "/usr/local/lib/python3.8/site-packages/flask/app.py", line 865, in dispatch_request
    return self.ensure_sync(self.view_functions[rule.endpoint])(**view_args)  # type: ignore[no-any-return]
  File "/app/favorite_routes.py", line 85, in get_favorites
    cursor.close()
UnboundLocalError: local variable 'cursor' referenced before assignment
2024-11-13 13:34:36,825 ERROR Exception on /favorite [GET]
Traceback (most recent call last):
  File "/usr/local/lib/python3.8/site-packages/flask/app.py", line 1473, in wsgi_app
    response = self.full_dispatch_request()
  File "/usr/local/lib/python3.8/site-packages/flask/app.py", line 882, in full_dispatch_request
    rv = self.handle_user_exception(e)
  File "/usr/local/lib/python3.8/site-packages/flask_cors/extension.py", line 194, in wrapped_function
    return cors_after_request(app.make_response(f(*args, **kwargs)))
  File "/usr/local/lib/python3.8/site-packages/flask/app.py", line 880, in full_dispatch_request
    rv = self.dispatch_request()
  File "/usr/local/lib/python3.8/site-packages/flask/app.py", line 865, in dispatch_request
    return self.ensure_sync(self.view_functions[rule.endpoint])(**view_args)  # type: ignore[no-any-return]
  File "/app/favorite_routes.py", line 85, in get_favorites
    cursor.close()
UnboundLocalError: local variable 'cursor' referenced before assignment
2024-11-13 13:34:40,060 ERROR Exception on /upload [POST]
Traceback (most recent call last):
  File "/usr/local/lib/python3.8/site-packages/flask/app.py", line 1473, in wsgi_app
    response = self.full_dispatch_request()
  File "/usr/local/lib/python3.8/site-packages/flask/app.py", line 882, in full_dispatch_request
    rv = self.handle_user_exception(e)
  File "/usr/local/lib/python3.8/site-packages/flask_cors/extension.py", line 194, in wrapped_function
    return cors_after_request(app.make_response(f(*args, **kwargs)))
  File "/usr/local/lib/python3.8/site-packages/flask/app.py", line 880, in full_dispatch_request
    rv = self.dispatch_request()
  File "/usr/local/lib/python3.8/site-packages/flask/app.py", line 865, in dispatch_request
    return self.ensure_sync(self.view_functions[rule.endpoint])(**view_args)  # type: ignore[no-any-return]
  File "/app/books_routes.py", line 79, in upload_data
    cursor.close()
UnboundLocalError: local variable 'cursor' referenced before assignment
2024-11-13 13:34:42,541 ERROR Exception on /favorite [GET]
Traceback (most recent call last):
  File "/usr/local/lib/python3.8/site-packages/flask/app.py", line 1473, in wsgi_app
    response = self.full_dispatch_request()
  File "/usr/local/lib/python3.8/site-packages/flask/app.py", line 882, in full_dispatch_request
    rv = self.handle_user_exception(e)
  File "/usr/local/lib/python3.8/site-packages/flask_cors/extension.py", line 194, in wrapped_function
    return cors_after_request(app.make_response(f(*args, **kwargs)))
  File "/usr/local/lib/python3.8/site-packages/flask/app.py", line 880, in full_dispatch_request
    rv = self.dispatch_request()
  File "/usr/local/lib/python3.8/site-packages/flask/app.py", line 865, in dispatch_request
    return self.ensure_sync(self.view_functions[rule.endpoint])(**view_args)  # type: ignore[no-any-return]
  File "/app/favorite_routes.py", line 85, in get_favorites
    cursor.close()
UnboundLocalError: local variable 'cursor' referenced before assignment
2024-11-13 13:34:43,279 ERROR Exception on /favorite [GET]
Traceback (most recent call last):
  File "/usr/local/lib/python3.8/site-packages/flask/app.py", line 1473, in wsgi_app
    response = self.full_dispatch_request()
  File "/usr/local/lib/python3.8/site-packages/flask/app.py", line 882, in full_dispatch_request
    rv = self.handle_user_exception(e)
  File "/usr/local/lib/python3.8/site-packages/flask_cors/extension.py", line 194, in wrapped_function
    return cors_after_request(app.make_response(f(*args, **kwargs)))
  File "/usr/local/lib/python3.8/site-packages/flask/app.py", line 880, in full_dispatch_request
    rv = self.dispatch_request()
  File "/usr/local/lib/python3.8/site-packages/flask/app.py", line 865, in dispatch_request
    return self.ensure_sync(self.view_functions[rule.endpoint])(**view_args)  # type: ignore[no-any-return]
  File "/app/favorite_routes.py", line 85, in get_favorites
    cursor.close()
UnboundLocalError: local variable 'cursor' referenced before assignment
2024-11-13 13:34:43,762 ERROR Exception on /favorite [GET]
Traceback (most recent call last):
  File "/usr/local/lib/python3.8/site-packages/flask/app.py", line 1473, in wsgi_app
    response = self.full_dispatch_request()
  File "/usr/local/lib/python3.8/site-packages/flask/app.py", line 882, in full_dispatch_request
    rv = self.handle_user_exception(e)
  File "/usr/local/lib/python3.8/site-packages/flask_cors/extension.py", line 194, in wrapped_function
    return cors_after_request(app.make_response(f(*args, **kwargs)))
  File "/usr/local/lib/python3.8/site-packages/flask/app.py", line 880, in full_dispatch_request
    rv = self.dispatch_request()
  File "/usr/local/lib/python3.8/site-packages/flask/app.py", line 865, in dispatch_request
    return self.ensure_sync(self.view_functions[rule.endpoint])(**view_args)  # type: ignore[no-any-return]
  File "/app/favorite_routes.py", line 85, in get_favorites
    cursor.close()
UnboundLocalError: local variable 'cursor' referenced before assignment
2024-11-13 13:58:09,220 ERROR Exception on /favorite [GET]
Traceback (most recent call last):
  File "/usr/local/lib/python3.8/site-packages/flask/app.py", line 1473, in wsgi_app
    response = self.full_dispatch_request()
  File "/usr/local/lib/python3.8/site-packages/flask/app.py", line 882, in full_dispatch_request
    rv = self.handle_user_exception(e)
  File "/usr/local/lib/python3.8/site-packages/flask_cors/extension.py", line 194, in wrapped_function
    return cors_after_request(app.make_response(f(*args, **kwargs)))
  File "/usr/local/lib/python3.8/site-packages/flask/app.py", line 880, in full_dispatch_request
    rv = self.dispatch_request()
  File "/usr/local/lib/python3.8/site-packages/flask/app.py", line 865, in dispatch_request
    return self.ensure_sync(self.view_functions[rule.endpoint])(**view_args)  # type: ignore[no-any-return]
  File "/app/favorite_routes.py", line 85, in get_favorites
    cursor.close()
UnboundLocalError: local variable 'cursor' referenced before assignment
